package ninjapancakes87.civilwar.world;

import java.util.Random;

import net.minecraft.block.Block;
import net.minecraft.init.Blocks;
import net.minecraft.item.Item;
import net.minecraft.item.ItemStack;
import net.minecraft.tileentity.TileEntityChest;
import net.minecraft.world.World;
import net.minecraft.world.gen.feature.WorldGenerator;
import ninjapancakes87.civilwar.Registry;

public class WorldGenSpawn extends WorldGenerator{

	public WorldGenSpawn(){
		
	}
   /* public boolean generate(World world, Random rand, int i, int j, int k)
    {
    	Block Grass = Blocks.grass;
    	Block wildGrass = Blocks.tallgrass;
    	Block firstcorner = world.getBlock(i, j, k);
    	Block secondcorner = world.getBlock(i + 12, j, k);
    	Block thirdcorner = world.getBlock(i + 12, j, k + 10);
    	Block fourthcorner = world.getBlock(i, j, k + 10);
    	Block center = world.getBlock(i, j, k);
    	int i1 = world.getBlockMetadata(i, j, k) & 4;
    	if(firstcorner != Grass || secondcorner != Grass || thirdcorner != Grass || fourthcorner != Grass ){
    		return false;    		
    	   }
    	if(firstcorner != wildGrass || secondcorner != wildGrass || thirdcorner != wildGrass || fourthcorner != wildGrass){   
			return false;
		}
    	
    		world.setBlock(i + 0, j + 0, k + 10, Blocks.grass);
            world.setBlock(i + 0, j + 0, k + 9, Blocks.grass);
            world.setBlock(i + 0, j + 0, k + 8, Blocks.grass);
            world.setBlock(i + 0, j + 0, k + 7, Blocks.grass);
            world.setBlock(i + 0, j + 0, k + 6, Blocks.grass);
            world.setBlock(i + 0, j + 0, k + 5, Blocks.grass);
            world.setBlock(i + 0, j + 0, k + 4, Blocks.grass);
            world.setBlock(i + 0, j + 0, k + 3, Blocks.grass);
            world.setBlock(i + 0, j + 0, k + 2, Blocks.grass);
            world.setBlock(i + 0, j + 0, k + 1, Blocks.grass);
            world.setBlock(i + 0, j + 0, k + 0, Blocks.grass);
            world.setBlock(i + 1, j + 0, k + 10, Blocks.grass);
            world.setBlock(i + 1, j + 0, k + 9, Blocks.grass);
            world.setBlock(i + 1, j + 0, k + 8, Blocks.grass);
            world.setBlock(i + 1, j + 0, k + 7, Blocks.grass);
            world.setBlock(i + 1, j + 0, k + 6, Blocks.grass);
            world.setBlock(i + 1, j + 0, k + 5, Blocks.grass);
            world.setBlock(i + 1, j + 0, k + 4, Blocks.grass);
            world.setBlock(i + 1, j + 0, k + 3, Blocks.grass);
            world.setBlock(i + 1, j + 0, k + 2, Blocks.grass);
            world.setBlock(i + 1, j + 0, k + 1, Blocks.grass);
            world.setBlock(i + 1, j + 0, k + 0, Blocks.grass);
            world.setBlock(i + 2, j + 0, k + 10, Blocks.grass);
            world.setBlock(i + 2, j + 0, k + 9, Blocks.grass);
            world.setBlock(i + 2, j + 0, k + 8, Blocks.);
            world.setBlock(i + 2, j + 0, k + 7, Blocks.brick);
            world.setBlock(i + 2, j + 0, k + 6, Blocks.brick);
            world.setBlock(i + 2, j + 0, k + 5, Blocks.netherrack);
            world.setBlock(i + 2, j + 0, k + 4, Blocks.brick);
            world.setBlock(i + 2, j + 0, k + 3, Blocks.brick);
            world.setBlock(i + 2, j + 0, k + 2, Blocks.brick);
            world.setBlock(i + 2, j + 0, k + 1, Blocks.grass);
            world.setBlock(i + 2, j + 0, k + 0, Blocks.grass);
            world.setBlock(i + 3, j + 0, k + 10, Blocks.grass);
            world.setBlock(i + 3, j + 0, k + 9, Blocks.grass);
            world.setBlock(i + 3, j + 0, k + 8, Blocks.brick);
            world.setBlockMetadataWithNotify(i + 3, j + 0, k + 7, Block.planks, 1);
            world.setBlockMetadataWithNotify(i + 3, j + 0, k + 6, Block.planks, 1);
            world.setBlockMetadataWithNotify(i + 3, j + 0, k + 5, Block.planks, 1);
            world.setBlockMetadataWithNotify(i + 3, j + 0, k + 4, Block.planks, 1);
            world.setBlockMetadataWithNotify(i + 3, j + 0, k + 3, Block.planks, 1);
            world.setBlock(i + 3, j + 0, k + 2, Block.brick);
            world.setBlock(i + 3, j + 0, k + 1, Block.grass);
            world.setBlock(i + 3, j + 0, k + 0, Block.grass);
            world.setBlock(i + 4, j + 0, k + 10, Block.grass);
            world.setBlock(i + 4, j + 0, k + 9, Block.grass);
            world.setBlock(i + 4, j + 0, k + 8, Block.brick);
            world.setBlockMetadataWithNotify(i + 4, j + 0, k + 7, Block.planks, 1);
            world.setBlockMetadataWithNotify(i + 4, j + 0, k + 6, Block.planks, 1);
            world.setBlockMetadataWithNotify(i + 4, j + 0, k + 5, Block.planks, 1);
            world.setBlockMetadataWithNotify(i + 4, j + 0, k + 4, Block.planks, 1);
            world.setBlockMetadataWithNotify(i + 4, j + 0, k + 3, Block.planks, 1);
            world.setBlock(i + 4, j + 0, k + 2, Block.brick);
            world.setBlock(i + 4, j + 0, k + 1, Block.grass);
            world.setBlock(i + 4, j + 0, k + 0, Block.grass);
            world.setBlock(i + 5, j + 0, k + 10, Block.grass);
            world.setBlock(i + 5, j + 0, k + 9, Block.grass);
            world.setBlock(i + 5, j + 0, k + 8, Block.brick);
            world.setBlockMetadataWithNotify(i + 5, j + 0, k + 7, Block.planks, 1);
            world.setBlockMetadataWithNotify(i + 5, j + 0, k + 6, Block.planks, 1);
            world.setBlockMetadataWithNotify(i + 5, j + 0, k + 5, Block.planks, 1);
            world.setBlockMetadataWithNotify(i + 5, j + 0, k + 4, Block.planks, 1);
            world.setBlockMetadataWithNotify(i + 5, j + 0, k + 3, Block.planks, 1);
            world.setBlock(i + 5, j + 0, k + 2, Block.brick);
            world.setBlock(i + 5, j + 0, k + 1, Block.grass);
            world.setBlock(i + 5, j + 0, k + 0, Block.grass);
            world.setBlock(i + 6, j + 0, k + 10, Block.grass);
            world.setBlock(i + 6, j + 0, k + 9, Block.grass);
            world.setBlock(i + 6, j + 0, k + 8, Block.brick);
            world.setBlockMetadataWithNotify(i + 6, j + 0, k + 7, Block.planks, 1);
            world.setBlockMetadataWithNotify(i + 6, j + 0, k + 6, Block.planks, 1);
            world.setBlockMetadataWithNotify(i + 6, j + 0, k + 5, Block.planks, 1);
            world.setBlockMetadataWithNotify(i + 6, j + 0, k + 4, Block.planks, 1);
            world.setBlockMetadataWithNotify(i + 6, j + 0, k + 3, Block.planks, 1);
            world.setBlock(i + 6, j + 0, k + 2, Block.brick);
            world.setBlock(i + 6, j + 0, k + 1, Block.grass);
            world.setBlock(i + 6, j + 0, k + 0, Block.grass);
            world.setBlock(i + 7, j + 0, k + 10, Block.grass);
            world.setBlock(i + 7, j + 0, k + 9, Block.grass);
            world.setBlock(i + 7, j + 0, k + 8, Block.brick);
            world.setBlockMetadataWithNotify(i + 7, j + 0, k + 7, Block.planks, 1);
            world.setBlockMetadataWithNotify(i + 7, j + 0, k + 6, Block.planks, 1);
            world.setBlockMetadataWithNotify(i + 7, j + 0, k + 5, Block.planks, 1);
            world.setBlockMetadataWithNotify(i + 7, j + 0, k + 4, Block.planks, 1);
            world.setBlockMetadataWithNotify(i + 7, j + 0, k + 3, Block.planks, 1);
            world.setBlock(i + 7, j + 0, k + 2, Block.brick);
            world.setBlock(i + 7, j + 0, k + 1, Block.grass);
            world.setBlock(i + 7, j + 0, k + 0, Block.grass);
            world.setBlock(i + 8, j + 0, k + 10, Block.grass);
            world.setBlock(i + 8, j + 0, k + 9, Block.grass);
            world.setBlock(i + 8, j + 0, k + 8, Block.brick);
            world.setBlock(i + 8, j + 0, k + 7, Block.brick);
            world.setBlock(i + 8, j + 0, k + 6, Block.brick);
            world.setBlock(i + 8, j + 0, k + 5, Block.brick);
            world.setBlock(i + 8, j + 0, k + 4, Block.brick);
            world.setBlock(i + 8, j + 0, k + 3, Block.brick);
            world.setBlock(i + 8, j + 0, k + 2, Block.brick);
            world.setBlock(i + 8, j + 0, k + 1, Block.grass);
            world.setBlock(i + 8, j + 0, k + 0, Block.grass);
            world.setBlock(i + 9, j + 0, k + 10, Block.cobblestone);
            world.setBlock(i + 9, j + 0, k + 9, Block.cobblestone);
            world.setBlock(i + 9, j + 0, k + 1, Block.grass);
            world.setBlock(i + 9, j + 0, k + 0, Block.grass);
            world.setBlock(i + 10, j + 0, k + 10, Block.grass);
            world.setBlock(i + 10, j + 0, k + 9, Block.grass);
            world.setBlock(i + 10, j + 0, k + 1, Block.grass);
            world.setBlock(i + 10, j + 0, k + 0, Block.grass);
            world.setBlock(i + 11, j + 0, k + 10, Block.grass);
            world.setBlock(i + 11, j + 0, k + 9, Block.grass);
            world.setBlock(i + 11, j + 0, k + 8, Block.grass);
            world.setBlock(i + 11, j + 0, k + 7, Block.grass);
            world.setBlock(i + 11, j + 0, k + 6, Block.grass);
            world.setBlock(i + 11, j + 0, k + 5, Block.grass);
            world.setBlock(i + 11, j + 0, k + 4, Block.grass);
            world.setBlock(i + 11, j + 0, k + 3, Block.grass);
            world.setBlock(i + 11, j + 0, k + 2, Block.grass);
            world.setBlock(i + 11, j + 0, k + 1, Block.grass);
            world.setBlock(i + 11, j + 0, k + 0, Block.grass);
            world.setBlock(i + 12, j + 0, k + 10, Block.grass);
            world.setBlock(i + 12, j + 0, k + 9, Block.grass);
            world.setBlock(i + 12, j + 0, k + 8, Block.grass);
            world.setBlock(i + 12, j + 0, k + 7, Block.grass);
            world.setBlock(i + 12, j + 0, k + 6, Block.grass);
            world.setBlock(i + 12, j + 0, k + 5, Block.grass);
            world.setBlock(i + 12, j + 0, k + 4, Block.grass);
            world.setBlock(i + 12, j + 0, k + 3, Block.grass);
            world.setBlock(i + 12, j + 0, k + 2, Block.grass);
            world.setBlock(i + 12, j + 0, k + 1, Block.grass);
            world.setBlock(i + 12, j + 0, k + 0, Block.grass);
            world.setBlock(i + 0, j + 1, k + 10, Block.fence);
            world.setBlock(i + 0, j + 1, k + 9, Block.fence);
            world.setBlock(i + 0, j + 1, k + 8, Block.fence);
            world.setBlock(i + 0, j + 1, k + 7, Block.fence);
            world.setBlock(i + 0, j + 1, k + 6, Block.fence);
            world.setBlock(i + 0, j + 1, k + 5, Block.fence);
            world.setBlock(i + 0, j + 1, k + 4, Block.fence);
            world.setBlock(i + 0, j + 1, k + 3, Block.fence);
            world.setBlock(i + 0, j + 1, k + 2, Block.fence);
            world.setBlock(i + 0, j + 1, k + 1, Block.fence);
            world.setBlock(i + 0, j + 1, k + 0, Block.fence);
            world.setBlock(i + 1, j + 1, k + 10, Block.fence);
            world.setBlock(i + 1, j + 1, k + 5, Block.brick);
            world.setBlock(i + 1, j + 1, k + 0, Block.fence);
            world.setBlock(i + 2, j + 1, k + 10, Block.fence);
            world.setBlock(i + 2, j + 1, k + 8, Block.brick);
            world.setBlock(i + 2, j + 1, k + 7, Block.brick);
            world.setBlock(i + 2, j + 1, k + 6, Block.brick);
            world.setBlock(i + 2, j + 1, k + 5, Block.fire);
            world.setBlock(i + 2, j + 1, k + 4, Block.brick);
            world.setBlock(i + 2, j + 1, k + 3, Block.brick);
            world.setBlock(i + 2, j + 1, k + 2, Block.brick);
            world.setBlock(i + 2, j + 1, k + 0, Block.fence);
            world.setBlock(i + 3, j + 1, k + 10, Block.fence);
            world.setBlock(i + 3, j + 1, k + 8, Block.brick);
            world.setBlock(i + 3, j + 1, k + 7, Block.fence);
            world.setBlock(i + 3, j + 1, k + 6, Block.stoneSingleSlab);
            world.setBlock(i + 3, j + 1, k + 5, Block.stoneSingleSlab);
            world.setBlock(i + 3, j + 1, k + 4, Block.stoneSingleSlab);
            world.setBlock(i + 3, j + 1, k + 3, Block.fence);
            world.setBlock(i + 3, j + 1, k + 2, Block.brick);
            world.setBlock(i + 3, j + 1, k + 0, Block.fence);
            world.setBlock(i + 4, j + 1, k + 10, Block.fence);
            world.setBlock(i + 4, j + 1, k + 8, Block.brick);
            world.setBlock(i + 4, j + 1, k + 2, Block.brick);
            world.setBlock(i + 4, j + 1, k + 0, Block.fence);
            world.setBlock(i + 5, j + 1, k + 10, Block.fence);
            world.setBlock(i + 5, j + 1, k + 8, Block.brick);
            world.setBlock(i + 5, j + 1, k + 2, Block.brick);
            world.setBlock(i + 5, j + 1, k + 0, Block.fence);
            world.setBlock(i + 6, j + 1, k + 10, Block.fence);
            world.setBlock(i + 6, j + 1, k + 8, Block.brick);
            world.setBlock(i + 6, j + 1, k + 3, Block.trapdoor);
            world.setBlock(i + 6, j + 1, k + 2, Block.brick);
            world.setBlock(i + 6, j + 1, k + 0, Block.fence);
            world.setBlock(i + 7, j + 1, k + 10, Block.fence);
            world.setBlock(i + 7, j + 1, k + 8, Block.brick);
            world.setBlock(i + 7, j + 1, k + 7, Block.ladder);
            world.setBlock(i + 7, j + 1, k + 5, Block.woodSingleSlab);
            world.setBlock(i + 7, j + 1, k + 4, Block.trapdoor);
            world.setBlock(i + 7, j + 1, k + 3, Block.grass);
            world.setBlock(i + 7, j + 1, k + 2, Block.brick);
            world.setBlock(i + 7, j + 1, k + 0, Block.fence);
            world.setBlock(i + 8, j + 1, k + 10, Block.fence);
            world.setBlock(i + 8, j + 1, k + 8, Block.brick);
            world.setBlock(i + 8, j + 1, k + 7, Block.brick);
            world.setBlock(i + 8, j + 1, k + 6, Block.brick);
            world.setBlock(i + 8, j + 1, k + 5, Block.stone);
            world.setBlock(i + 8, j + 1, k + 4, Block.brick);
            world.setBlock(i + 8, j + 1, k + 3, Block.brick);
            world.setBlock(i + 8, j + 1, k + 2, Block.brick);
            world.setBlock(i + 8, j + 1, k + 0, Block.fence);
            world.setBlock(i + 9, j + 1, k + 10, Block.fenceGate);
            world.setBlock(i + 9, j + 1, k + 8, Block.stairsWoodBirch);
            world.setBlockMetadataWithNotify(i + 9, j + 1, k + 7, Block.planks, 1);
            world.setBlockMetadataWithNotify(i + 9, j + 1, k + 6, Block.planks, 1);
            world.setBlockMetadataWithNotify(i + 9, j + 1, k + 5, Block.planks, 1);
            world.setBlockMetadataWithNotify(i + 9, j + 1, k + 4, Block.planks, 1);
            world.setBlockMetadataWithNotify(i + 9, j + 1, k + 3, Block.planks, 1);
            world.setBlockMetadataWithNotify(i + 9, j + 1, k + 2, Block.planks, 1);
            world.setBlock(i + 9, j + 1, k + 0, Block.fence);
            world.setBlock(i + 10, j + 1, k + 10, Block.fence);
            world.setBlockMetadataWithNotify(i + 10, j + 1, k + 8, Block.planks, 1);
            world.setBlockMetadataWithNotify(i + 10, j + 1, k + 7, Block.planks, 1);
            world.setBlockMetadataWithNotify(i + 10, j + 1, k + 6, Block.planks, 1);
            world.setBlockMetadataWithNotify(i + 10, j + 1, k + 5, Block.planks, 1);
            world.setBlockMetadataWithNotify(i + 10, j + 1, k + 4, Block.planks, 1);
            world.setBlockMetadataWithNotify(i + 10, j + 1, k + 3, Block.planks, 1);
            world.setBlockMetadataWithNotify(i + 10, j + 1, k + 2, Block.planks, 1);
            world.setBlock(i + 10, j + 1, k + 0, Block.fence);
            world.setBlock(i + 11, j + 1, k + 10, Block.fence);
            world.setBlock(i + 11, j + 1, k + 8, Block.plantRed);
            world.setBlock(i + 11, j + 1, k + 7, Block.plantRed);
            world.setBlock(i + 11, j + 1, k + 6, Block.plantRed);
            world.setBlock(i + 11, j + 1, k + 5, Block.plantRed);
            world.setBlock(i + 11, j + 1, k + 4, Block.plantRed);
            world.setBlock(i + 11, j + 1, k + 3, Block.plantRed);
            world.setBlock(i + 11, j + 1, k + 2, Block.plantRed);
            world.setBlock(i + 11, j + 1, k + 0, Block.fence);
            world.setBlock(i + 12, j + 1, k + 10, Block.fence);
            world.setBlock(i + 12, j + 1, k + 9, Block.fence);
            world.setBlock(i + 12, j + 1, k + 8, Block.fence);
            world.setBlock(i + 12, j + 1, k + 7, Block.fence);
            world.setBlock(i + 12, j + 1, k + 6, Block.fence);
            world.setBlock(i + 12, j + 1, k + 5, Block.fence);
            world.setBlock(i + 12, j + 1, k + 4, Block.fence);
            world.setBlock(i + 12, j + 1, k + 3, Block.fence);
            world.setBlock(i + 12, j + 1, k + 2, Block.fence);
            world.setBlock(i + 12, j + 1, k + 1, Block.fence);
            world.setBlock(i + 12, j + 1, k + 0, Block.fence);
            world.setBlock(i + 0, j + 2, k + 10, Block.torchWood);
            world.setBlock(i + 0, j + 2, k + 0, Block.torchWood);
            world.setBlock(i + 1, j + 2, k + 5, Block.brick);
            world.setBlock(i + 2, j + 2, k + 8, Block.brick);
            world.setBlock(i + 2, j + 2, k + 7, Block.brick);
            world.setBlock(i + 2, j + 2, k + 6, Block.brick);
            world.setBlock(i + 2, j + 2, k + 5, Block.glass);
            world.setBlock(i + 2, j + 2, k + 4, Block.brick);
            world.setBlock(i + 2, j + 2, k + 3, Block.brick);
            world.setBlock(i + 2, j + 2, k + 2, Block.brick);
            world.setBlock(i + 3, j + 2, k + 8, Block.brick);
            world.setBlock(i + 3, j + 2, k + 7, Block.pressurePlateStone);
            world.setBlock(i + 3, j + 2, k + 3, Block.pressurePlateStone);
            world.setBlock(i + 3, j + 2, k + 2, Block.brick);
            world.setBlock(i + 4, j + 2, k + 8, Block.brick);
            world.setBlock(i + 4, j + 2, k + 2, Block.brick);
            world.setBlock(i + 5, j + 2, k + 8, Block.thinGlass);
            world.setBlock(i + 5, j + 2, k + 2, Block.thinGlass);
            world.setBlock(i + 6, j + 2, k + 8, Block.brick);
            world.setBlock(i + 6, j + 2, k + 2, Block.brick);
            world.setBlock(i + 7, j + 2, k + 8, Block.brick);
            world.setBlock(i + 7, j + 2, k + 7, Block.ladder);
            world.setBlock(i + 7, j + 2, k + 3, Block.flowerPot);
            world.setBlock(i + 7, j + 2, k + 2, Block.brick);
            world.setBlock(i + 8, j + 2, k + 8, Block.brick);
            world.setBlock(i + 8, j + 2, k + 7, Block.brick);
            world.setBlock(i + 8, j + 2, k + 6, Block.brick);
            world.setBlock(i + 8, j + 2, k + 5, Block.doorWood);
            world.setBlock(i + 8, j + 2, k + 4, Block.brick);
            world.setBlock(i + 8, j + 2, k + 3, Block.brick);
            world.setBlock(i + 8, j + 2, k + 2, Block.brick);
            world.setBlock(i + 9, j + 2, k + 2, Block.fence);
            world.setBlock(i + 10, j + 2, k + 8, Block.fence);
            world.setBlock(i + 10, j + 2, k + 7, Block.fence);
            world.setBlock(i + 10, j + 2, k + 6, Block.fence);
            world.setBlock(i + 10, j + 2, k + 5, Block.fence);
            world.setBlock(i + 10, j + 2, k + 4, Block.fence);
            world.setBlock(i + 10, j + 2, k + 3, Block.fence);
            world.setBlock(i + 10, j + 2, k + 2, Block.fence);
            world.setBlock(i + 10, j + 2, k + 0, Block.torchWood);
            world.setBlock(i + 12, j + 2, k + 10, Block.torchWood);
            world.setBlock(i + 12, j + 2, k + 0, Block.torchWood);
            world.setBlock(i + 2, j + 3, k + 8, Block.brick);
            world.setBlock(i + 2, j + 3, k + 7, Block.brick);
            world.setBlock(i + 2, j + 3, k + 6, Block.brick);
            world.setBlock(i + 2, j + 3, k + 5, Block.brick);
            world.setBlock(i + 2, j + 3, k + 4, Block.brick);
            world.setBlock(i + 2, j + 3, k + 3, Block.brick);
            world.setBlock(i + 2, j + 3, k + 2, Block.brick);
            world.setBlock(i + 3, j + 3, k + 8, Block.brick);
            world.setBlock(i + 3, j + 3, k + 2, Block.brick);
            world.setBlock(i + 4, j + 3, k + 8, Block.brick);
            world.setBlock(i + 4, j + 3, k + 2, Block.brick);
            world.setBlock(i + 5, j + 3, k + 8, Block.thinGlass);
            world.setBlock(i + 5, j + 3, k + 2, Block.thinGlass);
            world.setBlock(i + 6, j + 3, k + 8, Block.brick);
            world.setBlock(i + 6, j + 3, k + 2, Block.brick);
            world.setBlock(i + 7, j + 3, k + 8, Block.brick);
            world.setBlock(i + 7, j + 3, k + 7, Block.ladder);
            world.setBlock(i + 7, j + 3, k + 2, Block.brick);
            world.setBlock(i + 8, j + 3, k + 8, Block.brick);
            world.setBlock(i + 8, j + 3, k + 7, Block.thinGlass);
            world.setBlock(i + 8, j + 3, k + 6, Block.brick);
            world.setBlock(i + 8, j + 3, k + 5, Block.doorWood);
            world.setBlock(i + 8, j + 3, k + 4, Block.brick);
            world.setBlock(i + 8, j + 3, k + 3, Block.thinGlass);
            world.setBlock(i + 8, j + 3, k + 2, Block.brick);
            world.setBlock(i + 10, j + 3, k + 8, Block.torchWood);
            world.setBlock(i + 10, j + 3, k + 2, Block.torchWood);
            world.setBlock(i + 2, j + 4, k + 8, Block.brick);
            world.setBlock(i + 2, j + 4, k + 7, Block.brick);
            world.setBlock(i + 2, j + 4, k + 6, Block.brick);
            world.setBlock(i + 2, j + 4, k + 5, Block.brick);
            world.setBlock(i + 2, j + 4, k + 4, Block.brick);
            world.setBlock(i + 2, j + 4, k + 3, Block.brick);
            world.setBlock(i + 2, j + 4, k + 2, Block.brick);
            world.setBlock(i + 3, j + 4, k + 8, Block.brick);
            world.setBlock(i + 3, j + 4, k + 2, Block.brick);
            world.setBlock(i + 4, j + 4, k + 8, Block.brick);
            world.setBlock(i + 4, j + 4, k + 2, Block.brick);
            world.setBlock(i + 5, j + 4, k + 8, Block.brick);
            world.setBlock(i + 5, j + 4, k + 2, Block.brick);
            world.setBlock(i + 6, j + 4, k + 8, Block.brick);
            world.setBlock(i + 6, j + 4, k + 2, Block.brick);
            world.setBlock(i + 7, j + 4, k + 8, Block.brick);
            world.setBlock(i + 7, j + 4, k + 7, Block.ladder);
            world.setBlock(i + 7, j + 4, k + 2, Block.brick);
            world.setBlock(i + 8, j + 4, k + 8, Block.brick);
            world.setBlock(i + 8, j + 4, k + 7, Block.thinGlass);
            world.setBlock(i + 8, j + 4, k + 6, Block.brick);
            world.setBlock(i + 8, j + 4, k + 5, Block.brick);
            world.setBlock(i + 8, j + 4, k + 4, Block.brick);
            world.setBlock(i + 8, j + 4, k + 3, Block.thinGlass);
            world.setBlock(i + 8, j + 4, k + 2, Block.brick);
            world.setBlock(i + 2, j + 5, k + 8, Block.brick);
            world.setBlock(i + 2, j + 5, k + 7, Block.brick);
            world.setBlock(i + 2, j + 5, k + 6, Block.brick);
            world.setBlock(i + 2, j + 5, k + 5, Block.brick);
            world.setBlock(i + 2, j + 5, k + 4, Block.brick);
            world.setBlock(i + 2, j + 5, k + 3, Block.brick);
            world.setBlock(i + 2, j + 5, k + 2, Block.brick);
            world.setBlock(i + 3, j + 5, k + 8, Block.brick);
            world.setBlockMetadataWithNotify(i + 3, j + 5, k + 7, Block.planks, 1);
            world.setBlockMetadataWithNotify(i + 3, j + 5, k + 6, Block.planks, 1);
            world.setBlockMetadataWithNotify(i + 3, j + 5, k + 5, Block.planks, 1);
            world.setBlockMetadataWithNotify(i + 3, j + 5, k + 4, Block.planks, 1);
            world.setBlockMetadataWithNotify(i + 3, j + 5, k + 3, Block.planks, 1);
            world.setBlock(i + 3, j + 5, k + 2, Block.brick);
            world.setBlock(i + 4, j + 5, k + 8, Block.brick);
            world.setBlockMetadataWithNotify(i + 4, j + 5, k + 7, Block.planks, 1);
            world.setBlockMetadataWithNotify(i + 4, j + 5, k + 6, Block.planks, 1);
            world.setBlockMetadataWithNotify(i + 4, j + 5, k + 5, Block.planks, 1);
            world.setBlockMetadataWithNotify(i + 4, j + 5, k + 4, Block.planks, 1);
            world.setBlockMetadataWithNotify(i + 4, j + 5, k + 3, Block.planks, 1);
            world.setBlock(i + 4, j + 5, k + 2, Block.brick);
            world.setBlock(i + 5, j + 5, k + 8, Block.brick);
            world.setBlockMetadataWithNotify(i + 5, j + 5, k + 7, Block.planks, 1);
            world.setBlockMetadataWithNotify(i + 5, j + 5, k + 6, Block.planks, 1);
            world.setBlockMetadataWithNotify(i + 5, j + 5, k + 5, Block.planks, 1);
            world.setBlockMetadataWithNotify(i + 5, j + 5, k + 4, Block.planks, 1);
            world.setBlockMetadataWithNotify(i + 5, j + 5, k + 3, Block.planks, 1);
            world.setBlock(i + 5, j + 5, k + 2, Block.brick);
            world.setBlock(i + 6, j + 5, k + 8, Block.brick);
            world.setBlockMetadataWithNotify(i + 6, j + 5, k + 7, Block.planks, 1);
            world.setBlockMetadataWithNotify(i + 6, j + 5, k + 6, Block.planks, 1);
            world.setBlockMetadataWithNotify(i + 6, j + 5, k + 5, Block.planks, 1);
            world.setBlockMetadataWithNotify(i + 6, j + 5, k + 4, Block.planks, 1);
            world.setBlockMetadataWithNotify(i + 6, j + 5, k + 3, Block.planks, 1);
            world.setBlock(i + 6, j + 5, k + 2, Block.brick);
            world.setBlock(i + 7, j + 5, k + 8, Block.brick);
            world.setBlock(i + 7, j + 5, k + 7, Block.ladder);
            world.setBlockMetadataWithNotify(i + 7, j + 5, k + 6, Block.planks, 1);
            world.setBlockMetadataWithNotify(i + 7, j + 5, k + 5, Block.planks, 1);
            world.setBlockMetadataWithNotify(i + 7, j + 5, k + 4, Block.planks, 1);
            world.setBlockMetadataWithNotify(i + 7, j + 5, k + 3, Block.planks, 1);
            world.setBlock(i + 7, j + 5, k + 2, Block.brick);
            world.setBlock(i + 8, j + 5, k + 9, Block.stairsWoodBirch);
            world.setBlock(i + 8, j + 5, k + 8, Block.brick);
            world.setBlock(i + 8, j + 5, k + 7, Block.brick);
            world.setBlock(i + 8, j + 5, k + 6, Block.brick);
            world.setBlock(i + 8, j + 5, k + 5, Block.brick);
            world.setBlock(i + 8, j + 5, k + 4, Block.brick);
            world.setBlock(i + 8, j + 5, k + 3, Block.brick);
            world.setBlock(i + 8, j + 5, k + 2, Block.brick);
            world.setBlock(i + 8, j + 5, k + 1, Block.stairsWoodBirch);
            world.setBlock(i + 9, j + 5, k + 9, Block.stairsWoodBirch);
            world.setBlock(i + 9, j + 5, k + 8, Block.stairsWoodBirch);
            world.setBlock(i + 9, j + 5, k + 7, Block.stairsWoodBirch);
            world.setBlock(i + 9, j + 5, k + 6, Block.stairsWoodBirch);
            world.setBlock(i + 9, j + 5, k + 5, Block.stairsWoodBirch);
            world.setBlock(i + 9, j + 5, k + 4, Block.stairsWoodBirch);
            world.setBlock(i + 9, j + 5, k + 3, Block.stairsWoodBirch);
            world.setBlock(i + 9, j + 5, k + 2, Block.stairsWoodBirch);
            world.setBlock(i + 9, j + 5, k + 1, Block.stairsWoodBirch);
            world.setBlock(i + 2, j + 6, k + 8, Block.brick);
            world.setBlock(i + 2, j + 6, k + 7, Block.brick);
            world.setBlock(i + 2, j + 6, k + 6, Block.brick);
            world.setBlock(i + 2, j + 6, k + 5, Block.brick);
            world.setBlock(i + 2, j + 6, k + 4, Block.brick);
            world.setBlock(i + 2, j + 6, k + 3, Block.brick);
            world.setBlock(i + 2, j + 6, k + 2, Block.brick);
            world.setBlock(i + 3, j + 6, k + 8, Block.brick);
            world.setBlock(i + 3, j + 6, k + 7, Block.fence);
            world.setBlock(i + 3, j + 6, k + 3, Block.bed);
            world.setBlock(i + 3, j + 6, k + 2, Block.brick);
            world.setBlock(i + 4, j + 6, k + 8, Block.brick);
            world.setBlock(i + 4, j + 6, k + 7, Block.fence);
            world.setBlock(i + 4, j + 6, k + 3, Block.bed);
            world.setBlock(i + 4, j + 6, k + 2, Block.brick);
            world.setBlock(i + 5, j + 6, k + 8, Block.brick);
            world.setBlock(i + 5, j + 6, k + 2, Block.brick);
            world.setBlock(i + 6, j + 6, k + 8, Block.brick);
            world.setBlockMetadataWithNotify(i + 6, j + 6, k + 4, Block.planks, 1);
            world.setBlock(i + 6, j + 6, k + 2, Block.brick);
            world.setBlock(i + 7, j + 6, k + 8, Block.brick);
            world.setBlock(i + 7, j + 6, k + 7, Block.ladder);
            world.setBlock(i + 7, j + 6, k + 3, Block.chest);
            TileEntityChest tileentitychest = new TileEntityChest();  //This defines a new variable 'tile entity chest'. Don't worry too much about it.
            world.setBlockTileEntity(i + 1, j + 1, k + 3, tileentitychest); //This states where this tile entity should be, which is the same coordinates as the chest.
           
            for(int g = 1; g < tileentitychest.getSizeInventory(); g++) //As above, creates a new integer 'g'.
            {
                int h = rand.nextInt(100); //Think of this as the item has a chance out of 100 to spawn
                if(h >= 1 && h <= 5) //This says that if h (as defined in the above line) is between one and five, a stack of the item will spawn. Therefore the chance of it spawning is 5 out of 100.
                {
                   tileentitychest.setInventorySlotContents(g, new ItemStack(Item.bread.itemID, rand.nextInt(5) + 1, 0)); //This says what the said stack is of, and how big it is
                }                                                                                                                                                                                                                                        //The stack will be atleast 1 (+1) plus any number between
                if(h >= 6 && h <= 10)                                                                                                                                                                                            //0 and 5 (rand.nextInt(5)).
                {
                   tileentitychest.setInventorySlotContents(g, new ItemStack(Item.helmetGold.itemID, 1, 0));
                }
                if(h >= 11 && h <= 12)
                {
                   tileentitychest.setInventorySlotContents(g, new ItemStack(Item.swordIron.itemID, 1, 0)); //Here there is no rand.nextInt because I want there to always be only one
                } 
                if(h >= 11 && h <= 12)
                {
                   tileentitychest.setInventorySlotContents(g, new ItemStack(Registry.musket.itemID, 1, 0)); 
                }  
                if(h >= 13 && h <= 20)
                {
                   tileentitychest.setInventorySlotContents(g, new ItemStack(Item.arrow.itemID, rand.nextInt(10) + 1, 0));
                }
                if(h >= 13 && h <= 20)
                {
                   tileentitychest.setInventorySlotContents(g, new ItemStack(Registry.musketball.itemID, rand.nextInt(10) + 1, 0));
                }
                if(h >= 21 && h <= 23)
                {
                   tileentitychest.setInventorySlotContents(g, new ItemStack(Item.bow.itemID, rand.nextInt(4) + 1, 0));
                }
            }
           
         
            world.setBlock(i + 7, j + 6, k + 2, Block.brick);
            world.setBlock(i + 8, j + 6, k + 8, Block.brick);
            world.setBlock(i + 8, j + 6, k + 7, Block.brick);
            world.setBlock(i + 8, j + 6, k + 6, Block.brick);
            world.setBlock(i + 8, j + 6, k + 5, Block.brick);
            world.setBlock(i + 8, j + 6, k + 4, Block.brick);
            world.setBlock(i + 8, j + 6, k + 3, Block.brick);
            world.setBlock(i + 8, j + 6, k + 2, Block.brick);
            world.setBlock(i + 2, j + 7, k + 8, Block.brick);
            world.setBlock(i + 2, j + 7, k + 7, Block.brick);
            world.setBlock(i + 2, j + 7, k + 6, Block.brick);
            world.setBlock(i + 2, j + 7, k + 5, Block.thinGlass);
            world.setBlock(i + 2, j + 7, k + 4, Block.brick);
            world.setBlock(i + 2, j + 7, k + 3, Block.brick);
            world.setBlock(i + 2, j + 7, k + 2, Block.brick);
            world.setBlock(i + 3, j + 7, k + 8, Block.brick);
            world.setBlock(i + 3, j + 7, k + 7, Block.pressurePlatePlanks);
            world.setBlock(i + 3, j + 7, k + 2, Block.brick);
            world.setBlock(i + 4, j + 7, k + 8, Block.brick);
            world.setBlock(i + 4, j + 7, k + 7, Block.pressurePlatePlanks);
            world.setBlock(i + 4, j + 7, k + 2, Block.brick);
            world.setBlock(i + 5, j + 7, k + 8, Block.thinGlass);
            world.setBlock(i + 5, j + 7, k + 2, Block.thinGlass);
            world.setBlock(i + 6, j + 7, k + 8, Block.brick);
            world.setBlock(i + 6, j + 7, k + 2, Block.brick);
            world.setBlock(i + 7, j + 7, k + 8, Block.brick);
            world.setBlock(i + 7, j + 7, k + 2, Block.brick);
            world.setBlock(i + 8, j + 7, k + 8, Block.brick);
            world.setBlock(i + 8, j + 7, k + 7, Block.brick);
            world.setBlock(i + 8, j + 7, k + 6, Block.brick);
            world.setBlock(i + 8, j + 7, k + 5, Block.thinGlass);
            world.setBlock(i + 8, j + 7, k + 4, Block.brick);
            world.setBlock(i + 8, j + 7, k + 3, Block.brick);
            world.setBlock(i + 8, j + 7, k + 2, Block.brick);
            world.setBlock(i + 2, j + 8, k + 8, Block.brick);
            world.setBlock(i + 2, j + 8, k + 7, Block.brick);
            world.setBlock(i + 2, j + 8, k + 6, Block.brick);
            world.setBlock(i + 2, j + 8, k + 5, Block.thinGlass);
            world.setBlock(i + 2, j + 8, k + 4, Block.brick);
            world.setBlock(i + 2, j + 8, k + 3, Block.brick);
            world.setBlock(i + 2, j + 8, k + 2, Block.brick);
            world.setBlock(i + 3, j + 8, k + 8, Block.brick);
            world.setBlock(i + 3, j + 8, k + 2, Block.brick);
            world.setBlock(i + 4, j + 8, k + 8, Block.brick);
            world.setBlock(i + 4, j + 8, k + 2, Block.brick);
            world.setBlock(i + 5, j + 8, k + 8, Block.thinGlass);
            world.setBlock(i + 5, j + 8, k + 5, Block.stone);
            world.setBlock(i + 5, j + 8, k + 2, Block.thinGlass);
            world.setBlock(i + 6, j + 8, k + 8, Block.brick);
            world.setBlock(i + 6, j + 8, k + 2, Block.brick);
            world.setBlock(i + 7, j + 8, k + 8, Block.brick);
            world.setBlock(i + 7, j + 8, k + 2, Block.brick);
            world.setBlock(i + 8, j + 8, k + 8, Block.brick);
            world.setBlock(i + 8, j + 8, k + 7, Block.brick);
            world.setBlock(i + 8, j + 8, k + 6, Block.brick);
            world.setBlock(i + 8, j + 8, k + 5, Block.thinGlass);
            world.setBlock(i + 8, j + 8, k + 4, Block.brick);
            world.setBlock(i + 8, j + 8, k + 3, Block.brick);
            world.setBlock(i + 8, j + 8, k + 2, Block.brick);
            world.setBlock(i + 2, j + 9, k + 8, Block.brick);
            world.setBlock(i + 2, j + 9, k + 7, Block.brick);
            world.setBlock(i + 2, j + 9, k + 6, Block.brick);
            world.setBlock(i + 2, j + 9, k + 5, Block.brick);
            world.setBlock(i + 2, j + 9, k + 4, Block.brick);
            world.setBlock(i + 2, j + 9, k + 3, Block.brick);
            world.setBlock(i + 2, j + 9, k + 2, Block.brick);
            world.setBlock(i + 3, j + 9, k + 8, Block.brick);
            world.setBlock(i + 3, j + 9, k + 2, Block.brick);
            world.setBlock(i + 4, j + 9, k + 8, Block.brick);
            world.setBlock(i + 4, j + 9, k + 2, Block.brick);
            world.setBlock(i + 5, j + 9, k + 8, Block.brick);
            world.setBlock(i + 5, j + 9, k + 2, Block.brick);
            world.setBlock(i + 6, j + 9, k + 8, Block.brick);
            world.setBlock(i + 6, j + 9, k + 2, Block.brick);
            world.setBlock(i + 7, j + 9, k + 8, Block.brick);
            world.setBlock(i + 7, j + 9, k + 2, Block.brick);
            world.setBlock(i + 8, j + 9, k + 8, Block.brick);
            world.setBlock(i + 8, j + 9, k + 7, Block.brick);
            world.setBlock(i + 8, j + 9, k + 6, Block.brick);
            world.setBlock(i + 8, j + 9, k + 5, Block.brick);
            world.setBlock(i + 8, j + 9, k + 4, Block.brick);
            world.setBlock(i + 8, j + 9, k + 3, Block.brick);
            world.setBlock(i + 8, j + 9, k + 2, Block.brick);
            world.setBlock(i + 1, j + 10, k + 9, Block.stairsWoodBirch);
            world.setBlock(i + 1, j + 10, k + 8, Block.stairsWoodBirch);
            world.setBlock(i + 1, j + 10, k + 7, Block.stairsWoodBirch);
            world.setBlock(i + 1, j + 10, k + 6, Block.stairsWoodBirch);
            world.setBlock(i + 1, j + 10, k + 5, Block.stairsWoodBirch);
            world.setBlock(i + 1, j + 10, k + 4, Block.stairsWoodBirch);
            world.setBlock(i + 1, j + 10, k + 3, Block.stairsWoodBirch);
            world.setBlock(i + 1, j + 10, k + 2, Block.stairsWoodBirch);
            world.setBlock(i + 1, j + 10, k + 1, Block.stairsWoodBirch);
            world.setBlock(i + 2, j + 10, k + 9, Block.stairsWoodBirch);
            world.setBlock(i + 2, j + 10, k + 8, Block.brick);
            world.setBlock(i + 2, j + 10, k + 7, Block.brick);
            world.setBlock(i + 2, j + 10, k + 6, Block.brick);
            world.setBlock(i + 2, j + 10, k + 5, Block.brick);
            world.setBlock(i + 2, j + 10, k + 4, Block.brick);
            world.setBlock(i + 2, j + 10, k + 3, Block.brick);
            world.setBlock(i + 2, j + 10, k + 2, Block.brick);
            world.setBlock(i + 2, j + 10, k + 1, Block.stairsWoodBirch);
            world.setBlock(i + 3, j + 10, k + 9, Block.stairsWoodBirch);
            world.setBlock(i + 3, j + 10, k + 8, Block.brick);
            world.setBlock(i + 3, j + 10, k + 7, Block.stoneSingleSlab);
            world.setBlock(i + 3, j + 10, k + 6, Block.stoneSingleSlab);
            world.setBlock(i + 3, j + 10, k + 5, Block.stoneSingleSlab);
            world.setBlock(i + 3, j + 10, k + 4, Block.stoneSingleSlab);
            world.setBlock(i + 3, j + 10, k + 3, Block.stoneSingleSlab);
            world.setBlock(i + 3, j + 10, k + 2, Block.brick);
            world.setBlock(i + 3, j + 10, k + 1, Block.stairsWoodBirch);
            world.setBlock(i + 4, j + 10, k + 9, Block.stairsWoodBirch);
            world.setBlock(i + 4, j + 10, k + 8, Block.brick);
            world.setBlock(i + 4, j + 10, k + 7, Block.stoneSingleSlab);
            world.setBlock(i + 4, j + 10, k + 6, Block.stoneSingleSlab);
            world.setBlock(i + 4, j + 10, k + 5, Block.stoneSingleSlab);
            world.setBlock(i + 4, j + 10, k + 4, Block.stoneSingleSlab);
            world.setBlock(i + 4, j + 10, k + 3, Block.stoneSingleSlab);
            world.setBlock(i + 4, j + 10, k + 2, Block.brick);
            world.setBlock(i + 4, j + 10, k + 1, Block.stairsWoodBirch);
            world.setBlock(i + 5, j + 10, k + 9, Block.stairsWoodBirch);
            world.setBlock(i + 5, j + 10, k + 8, Block.brick);
            world.setBlock(i + 5, j + 10, k + 7, Block.stoneSingleSlab);
            world.setBlock(i + 5, j + 10, k + 6, Block.stoneSingleSlab);
            world.setBlock(i + 5, j + 10, k + 5, Block.stoneSingleSlab);
            world.setBlock(i + 5, j + 10, k + 4, Block.stoneSingleSlab);
            world.setBlock(i + 5, j + 10, k + 3, Block.stoneSingleSlab);
            world.setBlock(i + 5, j + 10, k + 2, Block.brick);
            world.setBlock(i + 5, j + 10, k + 1, Block.stairsWoodBirch);
            world.setBlock(i + 6, j + 10, k + 9, Block.stairsWoodBirch);
            world.setBlock(i + 6, j + 10, k + 8, Block.brick);
            world.setBlock(i + 6, j + 10, k + 7, Block.stoneSingleSlab);
            world.setBlock(i + 6, j + 10, k + 6, Block.stoneSingleSlab);
            world.setBlock(i + 6, j + 10, k + 5, Block.stoneSingleSlab);
            world.setBlock(i + 6, j + 10, k + 4, Block.stoneSingleSlab);
            world.setBlock(i + 6, j + 10, k + 3, Block.stoneSingleSlab);
            world.setBlock(i + 6, j + 10, k + 2, Block.brick);
            world.setBlock(i + 6, j + 10, k + 1, Block.stairsWoodBirch);
            world.setBlock(i + 7, j + 10, k + 9, Block.stairsWoodBirch);
            world.setBlock(i + 7, j + 10, k + 8, Block.brick);
            world.setBlock(i + 7, j + 10, k + 7, Block.stoneSingleSlab);
            world.setBlock(i + 7, j + 10, k + 6, Block.stoneSingleSlab);
            world.setBlock(i + 7, j + 10, k + 5, Block.stoneSingleSlab);
            world.setBlock(i + 7, j + 10, k + 4, Block.stoneSingleSlab);
            world.setBlock(i + 7, j + 10, k + 3, Block.stoneSingleSlab);
            world.setBlock(i + 7, j + 10, k + 2, Block.brick);
            world.setBlock(i + 7, j + 10, k + 1, Block.stairsWoodBirch);
            world.setBlock(i + 8, j + 10, k + 9, Block.stairsWoodBirch);
            world.setBlock(i + 8, j + 10, k + 8, Block.brick);
            world.setBlock(i + 8, j + 10, k + 7, Block.brick);
            world.setBlock(i + 8, j + 10, k + 6, Block.brick);
            world.setBlock(i + 8, j + 10, k + 5, Block.brick);
            world.setBlock(i + 8, j + 10, k + 4, Block.brick);
            world.setBlock(i + 8, j + 10, k + 3, Block.brick);
            world.setBlock(i + 8, j + 10, k + 2, Block.brick);
            world.setBlock(i + 8, j + 10, k + 1, Block.stairsWoodBirch);
            world.setBlock(i + 9, j + 10, k + 9, Block.stairsWoodBirch);
            world.setBlock(i + 9, j + 10, k + 8, Block.stairsWoodBirch);
            world.setBlock(i + 9, j + 10, k + 7, Block.stairsWoodBirch);
            world.setBlock(i + 9, j + 10, k + 6, Block.stairsWoodBirch);
            world.setBlock(i + 9, j + 10, k + 5, Block.stairsWoodBirch);
            world.setBlock(i + 9, j + 10, k + 4, Block.stairsWoodBirch);
            world.setBlock(i + 9, j + 10, k + 3, Block.stairsWoodBirch);
            world.setBlock(i + 9, j + 10, k + 2, Block.stairsWoodBirch);
            world.setBlock(i + 9, j + 10, k + 1, Block.stairsWoodBirch);
            world.setBlock(i + 1, j + 11, k + 9, Block.stairsStoneBrick);
            world.setBlock(i + 1, j + 11, k + 8, Block.stairsStoneBrick);
            world.setBlock(i + 1, j + 11, k + 7, Block.stairsStoneBrick);
            world.setBlock(i + 1, j + 11, k + 6, Block.stairsStoneBrick);
            world.setBlock(i + 1, j + 11, k + 5, Block.stairsStoneBrick);
            world.setBlock(i + 1, j + 11, k + 4, Block.stairsStoneBrick);
            world.setBlock(i + 1, j + 11, k + 3, Block.stairsStoneBrick);
            world.setBlock(i + 1, j + 11, k + 2, Block.stairsStoneBrick);
            world.setBlock(i + 1, j + 11, k + 1, Block.stairsStoneBrick);
            world.setBlock(i + 2, j + 11, k + 9, Block.stairsStoneBrick);
            world.setBlock(i + 2, j + 11, k + 8, Block.brick);
            world.setBlock(i + 2, j + 11, k + 7, Block.brick);
            world.setBlock(i + 2, j + 11, k + 6, Block.brick);
            world.setBlock(i + 2, j + 11, k + 5, Block.brick);
            world.setBlock(i + 2, j + 11, k + 4, Block.brick);
            world.setBlock(i + 2, j + 11, k + 3, Block.brick);
            world.setBlock(i + 2, j + 11, k + 2, Block.brick);
            world.setBlock(i + 2, j + 11, k + 1, Block.stairsStoneBrick);
            world.setBlock(i + 3, j + 11, k + 9, Block.stairsStoneBrick);
            world.setBlock(i + 3, j + 11, k + 8, Block.brick);
            world.setBlock(i + 3, j + 11, k + 2, Block.brick);
            world.setBlock(i + 3, j + 11, k + 1, Block.stairsStoneBrick);
            world.setBlock(i + 4, j + 11, k + 9, Block.stairsStoneBrick);
            world.setBlock(i + 4, j + 11, k + 8, Block.brick);
            world.setBlock(i + 4, j + 11, k + 2, Block.brick);
            world.setBlock(i + 4, j + 11, k + 1, Block.stairsStoneBrick);
            world.setBlock(i + 5, j + 11, k + 9, Block.stairsStoneBrick);
            world.setBlock(i + 5, j + 11, k + 8, Block.brick);
            world.setBlock(i + 5, j + 11, k + 5, Block.glowStone);
            world.setBlock(i + 5, j + 11, k + 2, Block.brick);
            world.setBlock(i + 5, j + 11, k + 1, Block.stairsStoneBrick);
            world.setBlock(i + 6, j + 11, k + 9, Block.stairsStoneBrick);
            world.setBlock(i + 6, j + 11, k + 8, Block.brick);
            world.setBlock(i + 6, j + 11, k + 2, Block.brick);
            world.setBlock(i + 6, j + 11, k + 1, Block.stairsStoneBrick);
            world.setBlock(i + 7, j + 11, k + 9, Block.stairsStoneBrick);
            world.setBlock(i + 7, j + 11, k + 8, Block.brick);
            world.setBlock(i + 7, j + 11, k + 2, Block.brick);
            world.setBlock(i + 7, j + 11, k + 1, Block.stairsStoneBrick);
            world.setBlock(i + 8, j + 11, k + 9, Block.stairsStoneBrick);
            world.setBlock(i + 8, j + 11, k + 8, Block.brick);
            world.setBlock(i + 8, j + 11, k + 7, Block.brick);
            world.setBlock(i + 8, j + 11, k + 6, Block.brick);
            world.setBlock(i + 8, j + 11, k + 5, Block.brick);
            world.setBlock(i + 8, j + 11, k + 4, Block.brick);
            world.setBlock(i + 8, j + 11, k + 3, Block.brick);
            world.setBlock(i + 8, j + 11, k + 2, Block.brick);
            world.setBlock(i + 8, j + 11, k + 1, Block.stairsStoneBrick);
            world.setBlock(i + 9, j + 11, k + 9, Block.stairsStoneBrick);
            world.setBlock(i + 9, j + 11, k + 8, Block.stairsStoneBrick);
            world.setBlock(i + 9, j + 11, k + 7, Block.stairsStoneBrick);
            world.setBlock(i + 9, j + 11, k + 6, Block.stairsStoneBrick);
            world.setBlock(i + 9, j + 11, k + 5, Block.stairsStoneBrick);
            world.setBlock(i + 9, j + 11, k + 4, Block.stairsStoneBrick);
            world.setBlock(i + 9, j + 11, k + 3, Block.stairsStoneBrick);
            world.setBlock(i + 9, j + 11, k + 2, Block.stairsStoneBrick);
            world.setBlock(i + 9, j + 11, k + 1, Block.stairsStoneBrick);
            world.setBlock(i + 2, j + 12, k + 8, Block.stairsStoneBrick);
            world.setBlock(i + 2, j + 12, k + 7, Block.stairsStoneBrick);
            world.setBlock(i + 2, j + 12, k + 6, Block.stairsStoneBrick);
            world.setBlock(i + 2, j + 12, k + 5, Block.stairsStoneBrick);
            world.setBlock(i + 2, j + 12, k + 4, Block.stairsStoneBrick);
            world.setBlock(i + 2, j + 12, k + 3, Block.stairsStoneBrick);
            world.setBlock(i + 2, j + 12, k + 2, Block.stairsStoneBrick);
            world.setBlock(i + 3, j + 12, k + 8, Block.stairsStoneBrick);
            world.setBlock(i + 3, j + 12, k + 7, Block.stoneSingleSlab);
            world.setBlock(i + 3, j + 12, k + 6, Block.stoneSingleSlab);
            world.setBlock(i + 3, j + 12, k + 5, Block.stoneSingleSlab);
            world.setBlock(i + 3, j + 12, k + 4, Block.stoneSingleSlab);
            world.setBlock(i + 3, j + 12, k + 3, Block.stoneSingleSlab);
            world.setBlock(i + 3, j + 12, k + 2, Block.stairsStoneBrick);
            world.setBlock(i + 4, j + 12, k + 8, Block.stairsStoneBrick);
            world.setBlock(i + 4, j + 12, k + 7, Block.stoneSingleSlab);
            world.setBlock(i + 4, j + 12, k + 6, Block.stoneSingleSlab);
            world.setBlock(i + 4, j + 12, k + 5, Block.stoneSingleSlab);
            world.setBlock(i + 4, j + 12, k + 4, Block.stoneSingleSlab);
            world.setBlock(i + 4, j + 12, k + 3, Block.stoneSingleSlab);
            world.setBlock(i + 4, j + 12, k + 2, Block.stairsStoneBrick);
            world.setBlock(i + 5, j + 12, k + 8, Block.stairsStoneBrick);
            world.setBlock(i + 5, j + 12, k + 7, Block.stoneSingleSlab);
            world.setBlock(i + 5, j + 12, k + 6, Block.stoneSingleSlab);
            world.setBlock(i + 5, j + 12, k + 5, Block.stoneSingleSlab);
            world.setBlock(i + 5, j + 12, k + 4, Block.stoneSingleSlab);
            world.setBlock(i + 5, j + 12, k + 3, Block.stoneSingleSlab);
            world.setBlock(i + 5, j + 12, k + 2, Block.stairsStoneBrick);
            world.setBlock(i + 6, j + 12, k + 8, Block.stairsStoneBrick);
            world.setBlock(i + 6, j + 12, k + 7, Block.stoneSingleSlab);
            world.setBlock(i + 6, j + 12, k + 6, Block.stoneSingleSlab);
            world.setBlock(i + 6, j + 12, k + 5, Block.stoneSingleSlab);
            world.setBlock(i + 6, j + 12, k + 4, Block.stoneSingleSlab);
            world.setBlock(i + 6, j + 12, k + 3, Block.stoneSingleSlab);
            world.setBlock(i + 6, j + 12, k + 2, Block.stairsStoneBrick);
            world.setBlock(i + 7, j + 12, k + 8, Block.stairsStoneBrick);
            world.setBlock(i + 7, j + 12, k + 7, Block.stoneSingleSlab);
            world.setBlock(i + 7, j + 12, k + 6, Block.stoneSingleSlab);
            world.setBlock(i + 7, j + 12, k + 5, Block.stoneSingleSlab);
            world.setBlock(i + 7, j + 12, k + 4, Block.stoneSingleSlab);
            world.setBlock(i + 7, j + 12, k + 3, Block.stoneSingleSlab);
            world.setBlock(i + 7, j + 12, k + 2, Block.stairsStoneBrick);
            world.setBlock(i + 8, j + 12, k + 8, Block.stairsStoneBrick);
            world.setBlock(i + 8, j + 12, k + 7, Block.stairsStoneBrick);
            world.setBlock(i + 8, j + 12, k + 6, Block.stairsStoneBrick);
            world.setBlock(i + 8, j + 12, k + 5, Block.stairsStoneBrick);
            world.setBlock(i + 8, j + 12, k + 4, Block.stairsStoneBrick);
            world.setBlock(i + 8, j + 12, k + 3, Block.stairsStoneBrick);
            world.setBlock(i + 8, j + 12, k + 2, Block.stairsStoneBrick);
        
        return true;
    }
*/

	@Override
	public boolean generate(World var1, Random var2, int var3, int var4,
			int var5) {
		// TODO Auto-generated method stub
		return false;
	}
}
