package ninjapancakes87.civilwar.worldgen;

import java.util.Random;

import net.minecraft.block.Block;
import net.minecraft.item.Item;
import net.minecraft.item.ItemStack;
import net.minecraft.tileentity.TileEntityChest;
import net.minecraft.world.World;
import net.minecraft.world.gen.feature.WorldGenerator;
import ninjapancakes87.civilwar.Registry;

public class WorldGenSpawn extends WorldGenerator{

	public WorldGenSpawn(){
		
	}
    public boolean generate(World world, Random rand, int i, int j, int k)
    {
    	int Grass = Block.grass.blockID;
    	int wildGrass = Block.tallGrass.blockID;
    	int firstcorner = world.getBlockId(i, j, k);
    	int secondcorner = world.getBlockId(i + 12, j, k);
    	int thirdcorner = world.getBlockId(i + 12, j, k + 10);
    	int fourthcorner = world.getBlockId(i, j, k + 10);
    	int center = world.getBlockId(i, j, k);
    	int i1 = world.getBlockMetadata(i, j, k) & 4;
    	if(firstcorner != Grass || secondcorner != Grass || thirdcorner != Grass || fourthcorner != Grass ){
    		return false;    		
    	   }
    	if(firstcorner != wildGrass || secondcorner != wildGrass || thirdcorner != wildGrass || fourthcorner != wildGrass){   
			return false;
		}
    	
    		world.setBlock(i + 0, j + 0, k + 10, Block.grass.blockID);
            world.setBlock(i + 0, j + 0, k + 9, Block.grass.blockID);
            world.setBlock(i + 0, j + 0, k + 8, Block.grass.blockID);
            world.setBlock(i + 0, j + 0, k + 7, Block.grass.blockID);
            world.setBlock(i + 0, j + 0, k + 6, Block.grass.blockID);
            world.setBlock(i + 0, j + 0, k + 5, Block.grass.blockID);
            world.setBlock(i + 0, j + 0, k + 4, Block.grass.blockID);
            world.setBlock(i + 0, j + 0, k + 3, Block.grass.blockID);
            world.setBlock(i + 0, j + 0, k + 2, Block.grass.blockID);
            world.setBlock(i + 0, j + 0, k + 1, Block.grass.blockID);
            world.setBlock(i + 0, j + 0, k + 0, Block.grass.blockID);
            world.setBlock(i + 1, j + 0, k + 10, Block.grass.blockID);
            world.setBlock(i + 1, j + 0, k + 9, Block.grass.blockID);
            world.setBlock(i + 1, j + 0, k + 8, Block.grass.blockID);
            world.setBlock(i + 1, j + 0, k + 7, Block.grass.blockID);
            world.setBlock(i + 1, j + 0, k + 6, Block.grass.blockID);
            world.setBlock(i + 1, j + 0, k + 5, Block.grass.blockID);
            world.setBlock(i + 1, j + 0, k + 4, Block.grass.blockID);
            world.setBlock(i + 1, j + 0, k + 3, Block.grass.blockID);
            world.setBlock(i + 1, j + 0, k + 2, Block.grass.blockID);
            world.setBlock(i + 1, j + 0, k + 1, Block.grass.blockID);
            world.setBlock(i + 1, j + 0, k + 0, Block.grass.blockID);
            world.setBlock(i + 2, j + 0, k + 10, Block.grass.blockID);
            world.setBlock(i + 2, j + 0, k + 9, Block.grass.blockID);
            world.setBlock(i + 2, j + 0, k + 8, Block.brick.blockID);
            world.setBlock(i + 2, j + 0, k + 7, Block.brick.blockID);
            world.setBlock(i + 2, j + 0, k + 6, Block.brick.blockID);
            world.setBlock(i + 2, j + 0, k + 5, Block.netherrack.blockID);
            world.setBlock(i + 2, j + 0, k + 4, Block.brick.blockID);
            world.setBlock(i + 2, j + 0, k + 3, Block.brick.blockID);
            world.setBlock(i + 2, j + 0, k + 2, Block.brick.blockID);
            world.setBlock(i + 2, j + 0, k + 1, Block.grass.blockID);
            world.setBlock(i + 2, j + 0, k + 0, Block.grass.blockID);
            world.setBlock(i + 3, j + 0, k + 10, Block.grass.blockID);
            world.setBlock(i + 3, j + 0, k + 9, Block.grass.blockID);
            world.setBlock(i + 3, j + 0, k + 8, Block.brick.blockID);
            world.setBlockMetadataWithNotify(i + 3, j + 0, k + 7, Block.planks.blockID, 1);
            world.setBlockMetadataWithNotify(i + 3, j + 0, k + 6, Block.planks.blockID, 1);
            world.setBlockMetadataWithNotify(i + 3, j + 0, k + 5, Block.planks.blockID, 1);
            world.setBlockMetadataWithNotify(i + 3, j + 0, k + 4, Block.planks.blockID, 1);
            world.setBlockMetadataWithNotify(i + 3, j + 0, k + 3, Block.planks.blockID, 1);
            world.setBlock(i + 3, j + 0, k + 2, Block.brick.blockID);
            world.setBlock(i + 3, j + 0, k + 1, Block.grass.blockID);
            world.setBlock(i + 3, j + 0, k + 0, Block.grass.blockID);
            world.setBlock(i + 4, j + 0, k + 10, Block.grass.blockID);
            world.setBlock(i + 4, j + 0, k + 9, Block.grass.blockID);
            world.setBlock(i + 4, j + 0, k + 8, Block.brick.blockID);
            world.setBlockMetadataWithNotify(i + 4, j + 0, k + 7, Block.planks.blockID, 1);
            world.setBlockMetadataWithNotify(i + 4, j + 0, k + 6, Block.planks.blockID, 1);
            world.setBlockMetadataWithNotify(i + 4, j + 0, k + 5, Block.planks.blockID, 1);
            world.setBlockMetadataWithNotify(i + 4, j + 0, k + 4, Block.planks.blockID, 1);
            world.setBlockMetadataWithNotify(i + 4, j + 0, k + 3, Block.planks.blockID, 1);
            world.setBlock(i + 4, j + 0, k + 2, Block.brick.blockID);
            world.setBlock(i + 4, j + 0, k + 1, Block.grass.blockID);
            world.setBlock(i + 4, j + 0, k + 0, Block.grass.blockID);
            world.setBlock(i + 5, j + 0, k + 10, Block.grass.blockID);
            world.setBlock(i + 5, j + 0, k + 9, Block.grass.blockID);
            world.setBlock(i + 5, j + 0, k + 8, Block.brick.blockID);
            world.setBlockMetadataWithNotify(i + 5, j + 0, k + 7, Block.planks.blockID, 1);
            world.setBlockMetadataWithNotify(i + 5, j + 0, k + 6, Block.planks.blockID, 1);
            world.setBlockMetadataWithNotify(i + 5, j + 0, k + 5, Block.planks.blockID, 1);
            world.setBlockMetadataWithNotify(i + 5, j + 0, k + 4, Block.planks.blockID, 1);
            world.setBlockMetadataWithNotify(i + 5, j + 0, k + 3, Block.planks.blockID, 1);
            world.setBlock(i + 5, j + 0, k + 2, Block.brick.blockID);
            world.setBlock(i + 5, j + 0, k + 1, Block.grass.blockID);
            world.setBlock(i + 5, j + 0, k + 0, Block.grass.blockID);
            world.setBlock(i + 6, j + 0, k + 10, Block.grass.blockID);
            world.setBlock(i + 6, j + 0, k + 9, Block.grass.blockID);
            world.setBlock(i + 6, j + 0, k + 8, Block.brick.blockID);
            world.setBlockMetadataWithNotify(i + 6, j + 0, k + 7, Block.planks.blockID, 1);
            world.setBlockMetadataWithNotify(i + 6, j + 0, k + 6, Block.planks.blockID, 1);
            world.setBlockMetadataWithNotify(i + 6, j + 0, k + 5, Block.planks.blockID, 1);
            world.setBlockMetadataWithNotify(i + 6, j + 0, k + 4, Block.planks.blockID, 1);
            world.setBlockMetadataWithNotify(i + 6, j + 0, k + 3, Block.planks.blockID, 1);
            world.setBlock(i + 6, j + 0, k + 2, Block.brick.blockID);
            world.setBlock(i + 6, j + 0, k + 1, Block.grass.blockID);
            world.setBlock(i + 6, j + 0, k + 0, Block.grass.blockID);
            world.setBlock(i + 7, j + 0, k + 10, Block.grass.blockID);
            world.setBlock(i + 7, j + 0, k + 9, Block.grass.blockID);
            world.setBlock(i + 7, j + 0, k + 8, Block.brick.blockID);
            world.setBlockMetadataWithNotify(i + 7, j + 0, k + 7, Block.planks.blockID, 1);
            world.setBlockMetadataWithNotify(i + 7, j + 0, k + 6, Block.planks.blockID, 1);
            world.setBlockMetadataWithNotify(i + 7, j + 0, k + 5, Block.planks.blockID, 1);
            world.setBlockMetadataWithNotify(i + 7, j + 0, k + 4, Block.planks.blockID, 1);
            world.setBlockMetadataWithNotify(i + 7, j + 0, k + 3, Block.planks.blockID, 1);
            world.setBlock(i + 7, j + 0, k + 2, Block.brick.blockID);
            world.setBlock(i + 7, j + 0, k + 1, Block.grass.blockID);
            world.setBlock(i + 7, j + 0, k + 0, Block.grass.blockID);
            world.setBlock(i + 8, j + 0, k + 10, Block.grass.blockID);
            world.setBlock(i + 8, j + 0, k + 9, Block.grass.blockID);
            world.setBlock(i + 8, j + 0, k + 8, Block.brick.blockID);
            world.setBlock(i + 8, j + 0, k + 7, Block.brick.blockID);
            world.setBlock(i + 8, j + 0, k + 6, Block.brick.blockID);
            world.setBlock(i + 8, j + 0, k + 5, Block.brick.blockID);
            world.setBlock(i + 8, j + 0, k + 4, Block.brick.blockID);
            world.setBlock(i + 8, j + 0, k + 3, Block.brick.blockID);
            world.setBlock(i + 8, j + 0, k + 2, Block.brick.blockID);
            world.setBlock(i + 8, j + 0, k + 1, Block.grass.blockID);
            world.setBlock(i + 8, j + 0, k + 0, Block.grass.blockID);
            world.setBlock(i + 9, j + 0, k + 10, Block.cobblestone.blockID);
            world.setBlock(i + 9, j + 0, k + 9, Block.cobblestone.blockID);
            world.setBlock(i + 9, j + 0, k + 1, Block.grass.blockID);
            world.setBlock(i + 9, j + 0, k + 0, Block.grass.blockID);
            world.setBlock(i + 10, j + 0, k + 10, Block.grass.blockID);
            world.setBlock(i + 10, j + 0, k + 9, Block.grass.blockID);
            world.setBlock(i + 10, j + 0, k + 1, Block.grass.blockID);
            world.setBlock(i + 10, j + 0, k + 0, Block.grass.blockID);
            world.setBlock(i + 11, j + 0, k + 10, Block.grass.blockID);
            world.setBlock(i + 11, j + 0, k + 9, Block.grass.blockID);
            world.setBlock(i + 11, j + 0, k + 8, Block.grass.blockID);
            world.setBlock(i + 11, j + 0, k + 7, Block.grass.blockID);
            world.setBlock(i + 11, j + 0, k + 6, Block.grass.blockID);
            world.setBlock(i + 11, j + 0, k + 5, Block.grass.blockID);
            world.setBlock(i + 11, j + 0, k + 4, Block.grass.blockID);
            world.setBlock(i + 11, j + 0, k + 3, Block.grass.blockID);
            world.setBlock(i + 11, j + 0, k + 2, Block.grass.blockID);
            world.setBlock(i + 11, j + 0, k + 1, Block.grass.blockID);
            world.setBlock(i + 11, j + 0, k + 0, Block.grass.blockID);
            world.setBlock(i + 12, j + 0, k + 10, Block.grass.blockID);
            world.setBlock(i + 12, j + 0, k + 9, Block.grass.blockID);
            world.setBlock(i + 12, j + 0, k + 8, Block.grass.blockID);
            world.setBlock(i + 12, j + 0, k + 7, Block.grass.blockID);
            world.setBlock(i + 12, j + 0, k + 6, Block.grass.blockID);
            world.setBlock(i + 12, j + 0, k + 5, Block.grass.blockID);
            world.setBlock(i + 12, j + 0, k + 4, Block.grass.blockID);
            world.setBlock(i + 12, j + 0, k + 3, Block.grass.blockID);
            world.setBlock(i + 12, j + 0, k + 2, Block.grass.blockID);
            world.setBlock(i + 12, j + 0, k + 1, Block.grass.blockID);
            world.setBlock(i + 12, j + 0, k + 0, Block.grass.blockID);
            world.setBlock(i + 0, j + 1, k + 10, Block.fence.blockID);
            world.setBlock(i + 0, j + 1, k + 9, Block.fence.blockID);
            world.setBlock(i + 0, j + 1, k + 8, Block.fence.blockID);
            world.setBlock(i + 0, j + 1, k + 7, Block.fence.blockID);
            world.setBlock(i + 0, j + 1, k + 6, Block.fence.blockID);
            world.setBlock(i + 0, j + 1, k + 5, Block.fence.blockID);
            world.setBlock(i + 0, j + 1, k + 4, Block.fence.blockID);
            world.setBlock(i + 0, j + 1, k + 3, Block.fence.blockID);
            world.setBlock(i + 0, j + 1, k + 2, Block.fence.blockID);
            world.setBlock(i + 0, j + 1, k + 1, Block.fence.blockID);
            world.setBlock(i + 0, j + 1, k + 0, Block.fence.blockID);
            world.setBlock(i + 1, j + 1, k + 10, Block.fence.blockID);
            world.setBlock(i + 1, j + 1, k + 5, Block.brick.blockID);
            world.setBlock(i + 1, j + 1, k + 0, Block.fence.blockID);
            world.setBlock(i + 2, j + 1, k + 10, Block.fence.blockID);
            world.setBlock(i + 2, j + 1, k + 8, Block.brick.blockID);
            world.setBlock(i + 2, j + 1, k + 7, Block.brick.blockID);
            world.setBlock(i + 2, j + 1, k + 6, Block.brick.blockID);
            world.setBlock(i + 2, j + 1, k + 5, Block.fire.blockID);
            world.setBlock(i + 2, j + 1, k + 4, Block.brick.blockID);
            world.setBlock(i + 2, j + 1, k + 3, Block.brick.blockID);
            world.setBlock(i + 2, j + 1, k + 2, Block.brick.blockID);
            world.setBlock(i + 2, j + 1, k + 0, Block.fence.blockID);
            world.setBlock(i + 3, j + 1, k + 10, Block.fence.blockID);
            world.setBlock(i + 3, j + 1, k + 8, Block.brick.blockID);
            world.setBlock(i + 3, j + 1, k + 7, Block.fence.blockID);
            world.setBlock(i + 3, j + 1, k + 6, Block.stoneSingleSlab.blockID);
            world.setBlock(i + 3, j + 1, k + 5, Block.stoneSingleSlab.blockID);
            world.setBlock(i + 3, j + 1, k + 4, Block.stoneSingleSlab.blockID);
            world.setBlock(i + 3, j + 1, k + 3, Block.fence.blockID);
            world.setBlock(i + 3, j + 1, k + 2, Block.brick.blockID);
            world.setBlock(i + 3, j + 1, k + 0, Block.fence.blockID);
            world.setBlock(i + 4, j + 1, k + 10, Block.fence.blockID);
            world.setBlock(i + 4, j + 1, k + 8, Block.brick.blockID);
            world.setBlock(i + 4, j + 1, k + 2, Block.brick.blockID);
            world.setBlock(i + 4, j + 1, k + 0, Block.fence.blockID);
            world.setBlock(i + 5, j + 1, k + 10, Block.fence.blockID);
            world.setBlock(i + 5, j + 1, k + 8, Block.brick.blockID);
            world.setBlock(i + 5, j + 1, k + 2, Block.brick.blockID);
            world.setBlock(i + 5, j + 1, k + 0, Block.fence.blockID);
            world.setBlock(i + 6, j + 1, k + 10, Block.fence.blockID);
            world.setBlock(i + 6, j + 1, k + 8, Block.brick.blockID);
            world.setBlock(i + 6, j + 1, k + 3, Block.trapdoor.blockID);
            world.setBlock(i + 6, j + 1, k + 2, Block.brick.blockID);
            world.setBlock(i + 6, j + 1, k + 0, Block.fence.blockID);
            world.setBlock(i + 7, j + 1, k + 10, Block.fence.blockID);
            world.setBlock(i + 7, j + 1, k + 8, Block.brick.blockID);
            world.setBlock(i + 7, j + 1, k + 7, Block.ladder.blockID);
            world.setBlock(i + 7, j + 1, k + 5, Block.woodSingleSlab.blockID);
            world.setBlock(i + 7, j + 1, k + 4, Block.trapdoor.blockID);
            world.setBlock(i + 7, j + 1, k + 3, Block.grass.blockID);
            world.setBlock(i + 7, j + 1, k + 2, Block.brick.blockID);
            world.setBlock(i + 7, j + 1, k + 0, Block.fence.blockID);
            world.setBlock(i + 8, j + 1, k + 10, Block.fence.blockID);
            world.setBlock(i + 8, j + 1, k + 8, Block.brick.blockID);
            world.setBlock(i + 8, j + 1, k + 7, Block.brick.blockID);
            world.setBlock(i + 8, j + 1, k + 6, Block.brick.blockID);
            world.setBlock(i + 8, j + 1, k + 5, Block.stone.blockID);
            world.setBlock(i + 8, j + 1, k + 4, Block.brick.blockID);
            world.setBlock(i + 8, j + 1, k + 3, Block.brick.blockID);
            world.setBlock(i + 8, j + 1, k + 2, Block.brick.blockID);
            world.setBlock(i + 8, j + 1, k + 0, Block.fence.blockID);
            world.setBlock(i + 9, j + 1, k + 10, Block.fenceGate.blockID);
            world.setBlock(i + 9, j + 1, k + 8, Block.stairsWoodBirch.blockID);
            world.setBlockMetadataWithNotify(i + 9, j + 1, k + 7, Block.planks.blockID, 1);
            world.setBlockMetadataWithNotify(i + 9, j + 1, k + 6, Block.planks.blockID, 1);
            world.setBlockMetadataWithNotify(i + 9, j + 1, k + 5, Block.planks.blockID, 1);
            world.setBlockMetadataWithNotify(i + 9, j + 1, k + 4, Block.planks.blockID, 1);
            world.setBlockMetadataWithNotify(i + 9, j + 1, k + 3, Block.planks.blockID, 1);
            world.setBlockMetadataWithNotify(i + 9, j + 1, k + 2, Block.planks.blockID, 1);
            world.setBlock(i + 9, j + 1, k + 0, Block.fence.blockID);
            world.setBlock(i + 10, j + 1, k + 10, Block.fence.blockID);
            world.setBlockMetadataWithNotify(i + 10, j + 1, k + 8, Block.planks.blockID, 1);
            world.setBlockMetadataWithNotify(i + 10, j + 1, k + 7, Block.planks.blockID, 1);
            world.setBlockMetadataWithNotify(i + 10, j + 1, k + 6, Block.planks.blockID, 1);
            world.setBlockMetadataWithNotify(i + 10, j + 1, k + 5, Block.planks.blockID, 1);
            world.setBlockMetadataWithNotify(i + 10, j + 1, k + 4, Block.planks.blockID, 1);
            world.setBlockMetadataWithNotify(i + 10, j + 1, k + 3, Block.planks.blockID, 1);
            world.setBlockMetadataWithNotify(i + 10, j + 1, k + 2, Block.planks.blockID, 1);
            world.setBlock(i + 10, j + 1, k + 0, Block.fence.blockID);
            world.setBlock(i + 11, j + 1, k + 10, Block.fence.blockID);
            world.setBlock(i + 11, j + 1, k + 8, Block.plantRed.blockID);
            world.setBlock(i + 11, j + 1, k + 7, Block.plantRed.blockID);
            world.setBlock(i + 11, j + 1, k + 6, Block.plantRed.blockID);
            world.setBlock(i + 11, j + 1, k + 5, Block.plantRed.blockID);
            world.setBlock(i + 11, j + 1, k + 4, Block.plantRed.blockID);
            world.setBlock(i + 11, j + 1, k + 3, Block.plantRed.blockID);
            world.setBlock(i + 11, j + 1, k + 2, Block.plantRed.blockID);
            world.setBlock(i + 11, j + 1, k + 0, Block.fence.blockID);
            world.setBlock(i + 12, j + 1, k + 10, Block.fence.blockID);
            world.setBlock(i + 12, j + 1, k + 9, Block.fence.blockID);
            world.setBlock(i + 12, j + 1, k + 8, Block.fence.blockID);
            world.setBlock(i + 12, j + 1, k + 7, Block.fence.blockID);
            world.setBlock(i + 12, j + 1, k + 6, Block.fence.blockID);
            world.setBlock(i + 12, j + 1, k + 5, Block.fence.blockID);
            world.setBlock(i + 12, j + 1, k + 4, Block.fence.blockID);
            world.setBlock(i + 12, j + 1, k + 3, Block.fence.blockID);
            world.setBlock(i + 12, j + 1, k + 2, Block.fence.blockID);
            world.setBlock(i + 12, j + 1, k + 1, Block.fence.blockID);
            world.setBlock(i + 12, j + 1, k + 0, Block.fence.blockID);
            world.setBlock(i + 0, j + 2, k + 10, Block.torchWood.blockID);
            world.setBlock(i + 0, j + 2, k + 0, Block.torchWood.blockID);
            world.setBlock(i + 1, j + 2, k + 5, Block.brick.blockID);
            world.setBlock(i + 2, j + 2, k + 8, Block.brick.blockID);
            world.setBlock(i + 2, j + 2, k + 7, Block.brick.blockID);
            world.setBlock(i + 2, j + 2, k + 6, Block.brick.blockID);
            world.setBlock(i + 2, j + 2, k + 5, Block.glass.blockID);
            world.setBlock(i + 2, j + 2, k + 4, Block.brick.blockID);
            world.setBlock(i + 2, j + 2, k + 3, Block.brick.blockID);
            world.setBlock(i + 2, j + 2, k + 2, Block.brick.blockID);
            world.setBlock(i + 3, j + 2, k + 8, Block.brick.blockID);
            world.setBlock(i + 3, j + 2, k + 7, Block.pressurePlateStone.blockID);
            world.setBlock(i + 3, j + 2, k + 3, Block.pressurePlateStone.blockID);
            world.setBlock(i + 3, j + 2, k + 2, Block.brick.blockID);
            world.setBlock(i + 4, j + 2, k + 8, Block.brick.blockID);
            world.setBlock(i + 4, j + 2, k + 2, Block.brick.blockID);
            world.setBlock(i + 5, j + 2, k + 8, Block.thinGlass.blockID);
            world.setBlock(i + 5, j + 2, k + 2, Block.thinGlass.blockID);
            world.setBlock(i + 6, j + 2, k + 8, Block.brick.blockID);
            world.setBlock(i + 6, j + 2, k + 2, Block.brick.blockID);
            world.setBlock(i + 7, j + 2, k + 8, Block.brick.blockID);
            world.setBlock(i + 7, j + 2, k + 7, Block.ladder.blockID);
            world.setBlock(i + 7, j + 2, k + 3, Block.flowerPot.blockID);
            world.setBlock(i + 7, j + 2, k + 2, Block.brick.blockID);
            world.setBlock(i + 8, j + 2, k + 8, Block.brick.blockID);
            world.setBlock(i + 8, j + 2, k + 7, Block.brick.blockID);
            world.setBlock(i + 8, j + 2, k + 6, Block.brick.blockID);
            world.setBlock(i + 8, j + 2, k + 5, Block.doorWood.blockID);
            world.setBlock(i + 8, j + 2, k + 4, Block.brick.blockID);
            world.setBlock(i + 8, j + 2, k + 3, Block.brick.blockID);
            world.setBlock(i + 8, j + 2, k + 2, Block.brick.blockID);
            world.setBlock(i + 9, j + 2, k + 2, Block.fence.blockID);
            world.setBlock(i + 10, j + 2, k + 8, Block.fence.blockID);
            world.setBlock(i + 10, j + 2, k + 7, Block.fence.blockID);
            world.setBlock(i + 10, j + 2, k + 6, Block.fence.blockID);
            world.setBlock(i + 10, j + 2, k + 5, Block.fence.blockID);
            world.setBlock(i + 10, j + 2, k + 4, Block.fence.blockID);
            world.setBlock(i + 10, j + 2, k + 3, Block.fence.blockID);
            world.setBlock(i + 10, j + 2, k + 2, Block.fence.blockID);
            world.setBlock(i + 10, j + 2, k + 0, Block.torchWood.blockID);
            world.setBlock(i + 12, j + 2, k + 10, Block.torchWood.blockID);
            world.setBlock(i + 12, j + 2, k + 0, Block.torchWood.blockID);
            world.setBlock(i + 2, j + 3, k + 8, Block.brick.blockID);
            world.setBlock(i + 2, j + 3, k + 7, Block.brick.blockID);
            world.setBlock(i + 2, j + 3, k + 6, Block.brick.blockID);
            world.setBlock(i + 2, j + 3, k + 5, Block.brick.blockID);
            world.setBlock(i + 2, j + 3, k + 4, Block.brick.blockID);
            world.setBlock(i + 2, j + 3, k + 3, Block.brick.blockID);
            world.setBlock(i + 2, j + 3, k + 2, Block.brick.blockID);
            world.setBlock(i + 3, j + 3, k + 8, Block.brick.blockID);
            world.setBlock(i + 3, j + 3, k + 2, Block.brick.blockID);
            world.setBlock(i + 4, j + 3, k + 8, Block.brick.blockID);
            world.setBlock(i + 4, j + 3, k + 2, Block.brick.blockID);
            world.setBlock(i + 5, j + 3, k + 8, Block.thinGlass.blockID);
            world.setBlock(i + 5, j + 3, k + 2, Block.thinGlass.blockID);
            world.setBlock(i + 6, j + 3, k + 8, Block.brick.blockID);
            world.setBlock(i + 6, j + 3, k + 2, Block.brick.blockID);
            world.setBlock(i + 7, j + 3, k + 8, Block.brick.blockID);
            world.setBlock(i + 7, j + 3, k + 7, Block.ladder.blockID);
            world.setBlock(i + 7, j + 3, k + 2, Block.brick.blockID);
            world.setBlock(i + 8, j + 3, k + 8, Block.brick.blockID);
            world.setBlock(i + 8, j + 3, k + 7, Block.thinGlass.blockID);
            world.setBlock(i + 8, j + 3, k + 6, Block.brick.blockID);
            world.setBlock(i + 8, j + 3, k + 5, Block.doorWood.blockID);
            world.setBlock(i + 8, j + 3, k + 4, Block.brick.blockID);
            world.setBlock(i + 8, j + 3, k + 3, Block.thinGlass.blockID);
            world.setBlock(i + 8, j + 3, k + 2, Block.brick.blockID);
            world.setBlock(i + 10, j + 3, k + 8, Block.torchWood.blockID);
            world.setBlock(i + 10, j + 3, k + 2, Block.torchWood.blockID);
            world.setBlock(i + 2, j + 4, k + 8, Block.brick.blockID);
            world.setBlock(i + 2, j + 4, k + 7, Block.brick.blockID);
            world.setBlock(i + 2, j + 4, k + 6, Block.brick.blockID);
            world.setBlock(i + 2, j + 4, k + 5, Block.brick.blockID);
            world.setBlock(i + 2, j + 4, k + 4, Block.brick.blockID);
            world.setBlock(i + 2, j + 4, k + 3, Block.brick.blockID);
            world.setBlock(i + 2, j + 4, k + 2, Block.brick.blockID);
            world.setBlock(i + 3, j + 4, k + 8, Block.brick.blockID);
            world.setBlock(i + 3, j + 4, k + 2, Block.brick.blockID);
            world.setBlock(i + 4, j + 4, k + 8, Block.brick.blockID);
            world.setBlock(i + 4, j + 4, k + 2, Block.brick.blockID);
            world.setBlock(i + 5, j + 4, k + 8, Block.brick.blockID);
            world.setBlock(i + 5, j + 4, k + 2, Block.brick.blockID);
            world.setBlock(i + 6, j + 4, k + 8, Block.brick.blockID);
            world.setBlock(i + 6, j + 4, k + 2, Block.brick.blockID);
            world.setBlock(i + 7, j + 4, k + 8, Block.brick.blockID);
            world.setBlock(i + 7, j + 4, k + 7, Block.ladder.blockID);
            world.setBlock(i + 7, j + 4, k + 2, Block.brick.blockID);
            world.setBlock(i + 8, j + 4, k + 8, Block.brick.blockID);
            world.setBlock(i + 8, j + 4, k + 7, Block.thinGlass.blockID);
            world.setBlock(i + 8, j + 4, k + 6, Block.brick.blockID);
            world.setBlock(i + 8, j + 4, k + 5, Block.brick.blockID);
            world.setBlock(i + 8, j + 4, k + 4, Block.brick.blockID);
            world.setBlock(i + 8, j + 4, k + 3, Block.thinGlass.blockID);
            world.setBlock(i + 8, j + 4, k + 2, Block.brick.blockID);
            world.setBlock(i + 2, j + 5, k + 8, Block.brick.blockID);
            world.setBlock(i + 2, j + 5, k + 7, Block.brick.blockID);
            world.setBlock(i + 2, j + 5, k + 6, Block.brick.blockID);
            world.setBlock(i + 2, j + 5, k + 5, Block.brick.blockID);
            world.setBlock(i + 2, j + 5, k + 4, Block.brick.blockID);
            world.setBlock(i + 2, j + 5, k + 3, Block.brick.blockID);
            world.setBlock(i + 2, j + 5, k + 2, Block.brick.blockID);
            world.setBlock(i + 3, j + 5, k + 8, Block.brick.blockID);
            world.setBlockMetadataWithNotify(i + 3, j + 5, k + 7, Block.planks.blockID, 1);
            world.setBlockMetadataWithNotify(i + 3, j + 5, k + 6, Block.planks.blockID, 1);
            world.setBlockMetadataWithNotify(i + 3, j + 5, k + 5, Block.planks.blockID, 1);
            world.setBlockMetadataWithNotify(i + 3, j + 5, k + 4, Block.planks.blockID, 1);
            world.setBlockMetadataWithNotify(i + 3, j + 5, k + 3, Block.planks.blockID, 1);
            world.setBlock(i + 3, j + 5, k + 2, Block.brick.blockID);
            world.setBlock(i + 4, j + 5, k + 8, Block.brick.blockID);
            world.setBlockMetadataWithNotify(i + 4, j + 5, k + 7, Block.planks.blockID, 1);
            world.setBlockMetadataWithNotify(i + 4, j + 5, k + 6, Block.planks.blockID, 1);
            world.setBlockMetadataWithNotify(i + 4, j + 5, k + 5, Block.planks.blockID, 1);
            world.setBlockMetadataWithNotify(i + 4, j + 5, k + 4, Block.planks.blockID, 1);
            world.setBlockMetadataWithNotify(i + 4, j + 5, k + 3, Block.planks.blockID, 1);
            world.setBlock(i + 4, j + 5, k + 2, Block.brick.blockID);
            world.setBlock(i + 5, j + 5, k + 8, Block.brick.blockID);
            world.setBlockMetadataWithNotify(i + 5, j + 5, k + 7, Block.planks.blockID, 1);
            world.setBlockMetadataWithNotify(i + 5, j + 5, k + 6, Block.planks.blockID, 1);
            world.setBlockMetadataWithNotify(i + 5, j + 5, k + 5, Block.planks.blockID, 1);
            world.setBlockMetadataWithNotify(i + 5, j + 5, k + 4, Block.planks.blockID, 1);
            world.setBlockMetadataWithNotify(i + 5, j + 5, k + 3, Block.planks.blockID, 1);
            world.setBlock(i + 5, j + 5, k + 2, Block.brick.blockID);
            world.setBlock(i + 6, j + 5, k + 8, Block.brick.blockID);
            world.setBlockMetadataWithNotify(i + 6, j + 5, k + 7, Block.planks.blockID, 1);
            world.setBlockMetadataWithNotify(i + 6, j + 5, k + 6, Block.planks.blockID, 1);
            world.setBlockMetadataWithNotify(i + 6, j + 5, k + 5, Block.planks.blockID, 1);
            world.setBlockMetadataWithNotify(i + 6, j + 5, k + 4, Block.planks.blockID, 1);
            world.setBlockMetadataWithNotify(i + 6, j + 5, k + 3, Block.planks.blockID, 1);
            world.setBlock(i + 6, j + 5, k + 2, Block.brick.blockID);
            world.setBlock(i + 7, j + 5, k + 8, Block.brick.blockID);
            world.setBlock(i + 7, j + 5, k + 7, Block.ladder.blockID);
            world.setBlockMetadataWithNotify(i + 7, j + 5, k + 6, Block.planks.blockID, 1);
            world.setBlockMetadataWithNotify(i + 7, j + 5, k + 5, Block.planks.blockID, 1);
            world.setBlockMetadataWithNotify(i + 7, j + 5, k + 4, Block.planks.blockID, 1);
            world.setBlockMetadataWithNotify(i + 7, j + 5, k + 3, Block.planks.blockID, 1);
            world.setBlock(i + 7, j + 5, k + 2, Block.brick.blockID);
            world.setBlock(i + 8, j + 5, k + 9, Block.stairsWoodBirch.blockID);
            world.setBlock(i + 8, j + 5, k + 8, Block.brick.blockID);
            world.setBlock(i + 8, j + 5, k + 7, Block.brick.blockID);
            world.setBlock(i + 8, j + 5, k + 6, Block.brick.blockID);
            world.setBlock(i + 8, j + 5, k + 5, Block.brick.blockID);
            world.setBlock(i + 8, j + 5, k + 4, Block.brick.blockID);
            world.setBlock(i + 8, j + 5, k + 3, Block.brick.blockID);
            world.setBlock(i + 8, j + 5, k + 2, Block.brick.blockID);
            world.setBlock(i + 8, j + 5, k + 1, Block.stairsWoodBirch.blockID);
            world.setBlock(i + 9, j + 5, k + 9, Block.stairsWoodBirch.blockID);
            world.setBlock(i + 9, j + 5, k + 8, Block.stairsWoodBirch.blockID);
            world.setBlock(i + 9, j + 5, k + 7, Block.stairsWoodBirch.blockID);
            world.setBlock(i + 9, j + 5, k + 6, Block.stairsWoodBirch.blockID);
            world.setBlock(i + 9, j + 5, k + 5, Block.stairsWoodBirch.blockID);
            world.setBlock(i + 9, j + 5, k + 4, Block.stairsWoodBirch.blockID);
            world.setBlock(i + 9, j + 5, k + 3, Block.stairsWoodBirch.blockID);
            world.setBlock(i + 9, j + 5, k + 2, Block.stairsWoodBirch.blockID);
            world.setBlock(i + 9, j + 5, k + 1, Block.stairsWoodBirch.blockID);
            world.setBlock(i + 2, j + 6, k + 8, Block.brick.blockID);
            world.setBlock(i + 2, j + 6, k + 7, Block.brick.blockID);
            world.setBlock(i + 2, j + 6, k + 6, Block.brick.blockID);
            world.setBlock(i + 2, j + 6, k + 5, Block.brick.blockID);
            world.setBlock(i + 2, j + 6, k + 4, Block.brick.blockID);
            world.setBlock(i + 2, j + 6, k + 3, Block.brick.blockID);
            world.setBlock(i + 2, j + 6, k + 2, Block.brick.blockID);
            world.setBlock(i + 3, j + 6, k + 8, Block.brick.blockID);
            world.setBlock(i + 3, j + 6, k + 7, Block.fence.blockID);
            world.setBlock(i + 3, j + 6, k + 3, Block.bed.blockID);
            world.setBlock(i + 3, j + 6, k + 2, Block.brick.blockID);
            world.setBlock(i + 4, j + 6, k + 8, Block.brick.blockID);
            world.setBlock(i + 4, j + 6, k + 7, Block.fence.blockID);
            world.setBlock(i + 4, j + 6, k + 3, Block.bed.blockID);
            world.setBlock(i + 4, j + 6, k + 2, Block.brick.blockID);
            world.setBlock(i + 5, j + 6, k + 8, Block.brick.blockID);
            world.setBlock(i + 5, j + 6, k + 2, Block.brick.blockID);
            world.setBlock(i + 6, j + 6, k + 8, Block.brick.blockID);
            world.setBlockMetadataWithNotify(i + 6, j + 6, k + 4, Block.planks.blockID, 1);
            world.setBlock(i + 6, j + 6, k + 2, Block.brick.blockID);
            world.setBlock(i + 7, j + 6, k + 8, Block.brick.blockID);
            world.setBlock(i + 7, j + 6, k + 7, Block.ladder.blockID);
            world.setBlock(i + 7, j + 6, k + 3, Block.chest.blockID);
            TileEntityChest tileentitychest = new TileEntityChest();  //This defines a new variable 'tile entity chest'. Don't worry too much about it.
            world.setBlockTileEntity(i + 1, j + 1, k + 3, tileentitychest); //This states where this tile entity should be, which is the same coordinates as the chest.
           
            for(int g = 1; g < tileentitychest.getSizeInventory(); g++) //As above, creates a new integer 'g'.
            {
                int h = rand.nextInt(100); //Think of this as the item has a chance out of 100 to spawn
                if(h >= 1 && h <= 5) //This says that if h (as defined in the above line) is between one and five, a stack of the item will spawn. Therefore the chance of it spawning is 5 out of 100.
                {
                   tileentitychest.setInventorySlotContents(g, new ItemStack(Item.bread.itemID, rand.nextInt(5) + 1, 0)); //This says what the said stack is of, and how big it is
                }                                                                                                                                                                                                                                        //The stack will be atleast 1 (+1) plus any number between
                if(h >= 6 && h <= 10)                                                                                                                                                                                            //0 and 5 (rand.nextInt(5)).
                {
                   tileentitychest.setInventorySlotContents(g, new ItemStack(Item.helmetGold.itemID, 1, 0));
                }
                if(h >= 11 && h <= 12)
                {
                   tileentitychest.setInventorySlotContents(g, new ItemStack(Item.swordIron.itemID, 1, 0)); //Here there is no rand.nextInt because I want there to always be only one
                } 
                if(h >= 11 && h <= 12)
                {
                   tileentitychest.setInventorySlotContents(g, new ItemStack(Registry.musket.itemID, 1, 0)); 
                }  
                if(h >= 13 && h <= 20)
                {
                   tileentitychest.setInventorySlotContents(g, new ItemStack(Item.arrow.itemID, rand.nextInt(10) + 1, 0));
                }
                if(h >= 13 && h <= 20)
                {
                   tileentitychest.setInventorySlotContents(g, new ItemStack(Registry.musketball.itemID, rand.nextInt(10) + 1, 0));
                }
                if(h >= 21 && h <= 23)
                {
                   tileentitychest.setInventorySlotContents(g, new ItemStack(Item.bow.itemID, rand.nextInt(4) + 1, 0));
                }
            }
           
         
            world.setBlock(i + 7, j + 6, k + 2, Block.brick.blockID);
            world.setBlock(i + 8, j + 6, k + 8, Block.brick.blockID);
            world.setBlock(i + 8, j + 6, k + 7, Block.brick.blockID);
            world.setBlock(i + 8, j + 6, k + 6, Block.brick.blockID);
            world.setBlock(i + 8, j + 6, k + 5, Block.brick.blockID);
            world.setBlock(i + 8, j + 6, k + 4, Block.brick.blockID);
            world.setBlock(i + 8, j + 6, k + 3, Block.brick.blockID);
            world.setBlock(i + 8, j + 6, k + 2, Block.brick.blockID);
            world.setBlock(i + 2, j + 7, k + 8, Block.brick.blockID);
            world.setBlock(i + 2, j + 7, k + 7, Block.brick.blockID);
            world.setBlock(i + 2, j + 7, k + 6, Block.brick.blockID);
            world.setBlock(i + 2, j + 7, k + 5, Block.thinGlass.blockID);
            world.setBlock(i + 2, j + 7, k + 4, Block.brick.blockID);
            world.setBlock(i + 2, j + 7, k + 3, Block.brick.blockID);
            world.setBlock(i + 2, j + 7, k + 2, Block.brick.blockID);
            world.setBlock(i + 3, j + 7, k + 8, Block.brick.blockID);
            world.setBlock(i + 3, j + 7, k + 7, Block.pressurePlatePlanks.blockID);
            world.setBlock(i + 3, j + 7, k + 2, Block.brick.blockID);
            world.setBlock(i + 4, j + 7, k + 8, Block.brick.blockID);
            world.setBlock(i + 4, j + 7, k + 7, Block.pressurePlatePlanks.blockID);
            world.setBlock(i + 4, j + 7, k + 2, Block.brick.blockID);
            world.setBlock(i + 5, j + 7, k + 8, Block.thinGlass.blockID);
            world.setBlock(i + 5, j + 7, k + 2, Block.thinGlass.blockID);
            world.setBlock(i + 6, j + 7, k + 8, Block.brick.blockID);
            world.setBlock(i + 6, j + 7, k + 2, Block.brick.blockID);
            world.setBlock(i + 7, j + 7, k + 8, Block.brick.blockID);
            world.setBlock(i + 7, j + 7, k + 2, Block.brick.blockID);
            world.setBlock(i + 8, j + 7, k + 8, Block.brick.blockID);
            world.setBlock(i + 8, j + 7, k + 7, Block.brick.blockID);
            world.setBlock(i + 8, j + 7, k + 6, Block.brick.blockID);
            world.setBlock(i + 8, j + 7, k + 5, Block.thinGlass.blockID);
            world.setBlock(i + 8, j + 7, k + 4, Block.brick.blockID);
            world.setBlock(i + 8, j + 7, k + 3, Block.brick.blockID);
            world.setBlock(i + 8, j + 7, k + 2, Block.brick.blockID);
            world.setBlock(i + 2, j + 8, k + 8, Block.brick.blockID);
            world.setBlock(i + 2, j + 8, k + 7, Block.brick.blockID);
            world.setBlock(i + 2, j + 8, k + 6, Block.brick.blockID);
            world.setBlock(i + 2, j + 8, k + 5, Block.thinGlass.blockID);
            world.setBlock(i + 2, j + 8, k + 4, Block.brick.blockID);
            world.setBlock(i + 2, j + 8, k + 3, Block.brick.blockID);
            world.setBlock(i + 2, j + 8, k + 2, Block.brick.blockID);
            world.setBlock(i + 3, j + 8, k + 8, Block.brick.blockID);
            world.setBlock(i + 3, j + 8, k + 2, Block.brick.blockID);
            world.setBlock(i + 4, j + 8, k + 8, Block.brick.blockID);
            world.setBlock(i + 4, j + 8, k + 2, Block.brick.blockID);
            world.setBlock(i + 5, j + 8, k + 8, Block.thinGlass.blockID);
            world.setBlock(i + 5, j + 8, k + 5, Block.stone.blockID);
            world.setBlock(i + 5, j + 8, k + 2, Block.thinGlass.blockID);
            world.setBlock(i + 6, j + 8, k + 8, Block.brick.blockID);
            world.setBlock(i + 6, j + 8, k + 2, Block.brick.blockID);
            world.setBlock(i + 7, j + 8, k + 8, Block.brick.blockID);
            world.setBlock(i + 7, j + 8, k + 2, Block.brick.blockID);
            world.setBlock(i + 8, j + 8, k + 8, Block.brick.blockID);
            world.setBlock(i + 8, j + 8, k + 7, Block.brick.blockID);
            world.setBlock(i + 8, j + 8, k + 6, Block.brick.blockID);
            world.setBlock(i + 8, j + 8, k + 5, Block.thinGlass.blockID);
            world.setBlock(i + 8, j + 8, k + 4, Block.brick.blockID);
            world.setBlock(i + 8, j + 8, k + 3, Block.brick.blockID);
            world.setBlock(i + 8, j + 8, k + 2, Block.brick.blockID);
            world.setBlock(i + 2, j + 9, k + 8, Block.brick.blockID);
            world.setBlock(i + 2, j + 9, k + 7, Block.brick.blockID);
            world.setBlock(i + 2, j + 9, k + 6, Block.brick.blockID);
            world.setBlock(i + 2, j + 9, k + 5, Block.brick.blockID);
            world.setBlock(i + 2, j + 9, k + 4, Block.brick.blockID);
            world.setBlock(i + 2, j + 9, k + 3, Block.brick.blockID);
            world.setBlock(i + 2, j + 9, k + 2, Block.brick.blockID);
            world.setBlock(i + 3, j + 9, k + 8, Block.brick.blockID);
            world.setBlock(i + 3, j + 9, k + 2, Block.brick.blockID);
            world.setBlock(i + 4, j + 9, k + 8, Block.brick.blockID);
            world.setBlock(i + 4, j + 9, k + 2, Block.brick.blockID);
            world.setBlock(i + 5, j + 9, k + 8, Block.brick.blockID);
            world.setBlock(i + 5, j + 9, k + 2, Block.brick.blockID);
            world.setBlock(i + 6, j + 9, k + 8, Block.brick.blockID);
            world.setBlock(i + 6, j + 9, k + 2, Block.brick.blockID);
            world.setBlock(i + 7, j + 9, k + 8, Block.brick.blockID);
            world.setBlock(i + 7, j + 9, k + 2, Block.brick.blockID);
            world.setBlock(i + 8, j + 9, k + 8, Block.brick.blockID);
            world.setBlock(i + 8, j + 9, k + 7, Block.brick.blockID);
            world.setBlock(i + 8, j + 9, k + 6, Block.brick.blockID);
            world.setBlock(i + 8, j + 9, k + 5, Block.brick.blockID);
            world.setBlock(i + 8, j + 9, k + 4, Block.brick.blockID);
            world.setBlock(i + 8, j + 9, k + 3, Block.brick.blockID);
            world.setBlock(i + 8, j + 9, k + 2, Block.brick.blockID);
            world.setBlock(i + 1, j + 10, k + 9, Block.stairsWoodBirch.blockID);
            world.setBlock(i + 1, j + 10, k + 8, Block.stairsWoodBirch.blockID);
            world.setBlock(i + 1, j + 10, k + 7, Block.stairsWoodBirch.blockID);
            world.setBlock(i + 1, j + 10, k + 6, Block.stairsWoodBirch.blockID);
            world.setBlock(i + 1, j + 10, k + 5, Block.stairsWoodBirch.blockID);
            world.setBlock(i + 1, j + 10, k + 4, Block.stairsWoodBirch.blockID);
            world.setBlock(i + 1, j + 10, k + 3, Block.stairsWoodBirch.blockID);
            world.setBlock(i + 1, j + 10, k + 2, Block.stairsWoodBirch.blockID);
            world.setBlock(i + 1, j + 10, k + 1, Block.stairsWoodBirch.blockID);
            world.setBlock(i + 2, j + 10, k + 9, Block.stairsWoodBirch.blockID);
            world.setBlock(i + 2, j + 10, k + 8, Block.brick.blockID);
            world.setBlock(i + 2, j + 10, k + 7, Block.brick.blockID);
            world.setBlock(i + 2, j + 10, k + 6, Block.brick.blockID);
            world.setBlock(i + 2, j + 10, k + 5, Block.brick.blockID);
            world.setBlock(i + 2, j + 10, k + 4, Block.brick.blockID);
            world.setBlock(i + 2, j + 10, k + 3, Block.brick.blockID);
            world.setBlock(i + 2, j + 10, k + 2, Block.brick.blockID);
            world.setBlock(i + 2, j + 10, k + 1, Block.stairsWoodBirch.blockID);
            world.setBlock(i + 3, j + 10, k + 9, Block.stairsWoodBirch.blockID);
            world.setBlock(i + 3, j + 10, k + 8, Block.brick.blockID);
            world.setBlock(i + 3, j + 10, k + 7, Block.stoneSingleSlab.blockID);
            world.setBlock(i + 3, j + 10, k + 6, Block.stoneSingleSlab.blockID);
            world.setBlock(i + 3, j + 10, k + 5, Block.stoneSingleSlab.blockID);
            world.setBlock(i + 3, j + 10, k + 4, Block.stoneSingleSlab.blockID);
            world.setBlock(i + 3, j + 10, k + 3, Block.stoneSingleSlab.blockID);
            world.setBlock(i + 3, j + 10, k + 2, Block.brick.blockID);
            world.setBlock(i + 3, j + 10, k + 1, Block.stairsWoodBirch.blockID);
            world.setBlock(i + 4, j + 10, k + 9, Block.stairsWoodBirch.blockID);
            world.setBlock(i + 4, j + 10, k + 8, Block.brick.blockID);
            world.setBlock(i + 4, j + 10, k + 7, Block.stoneSingleSlab.blockID);
            world.setBlock(i + 4, j + 10, k + 6, Block.stoneSingleSlab.blockID);
            world.setBlock(i + 4, j + 10, k + 5, Block.stoneSingleSlab.blockID);
            world.setBlock(i + 4, j + 10, k + 4, Block.stoneSingleSlab.blockID);
            world.setBlock(i + 4, j + 10, k + 3, Block.stoneSingleSlab.blockID);
            world.setBlock(i + 4, j + 10, k + 2, Block.brick.blockID);
            world.setBlock(i + 4, j + 10, k + 1, Block.stairsWoodBirch.blockID);
            world.setBlock(i + 5, j + 10, k + 9, Block.stairsWoodBirch.blockID);
            world.setBlock(i + 5, j + 10, k + 8, Block.brick.blockID);
            world.setBlock(i + 5, j + 10, k + 7, Block.stoneSingleSlab.blockID);
            world.setBlock(i + 5, j + 10, k + 6, Block.stoneSingleSlab.blockID);
            world.setBlock(i + 5, j + 10, k + 5, Block.stoneSingleSlab.blockID);
            world.setBlock(i + 5, j + 10, k + 4, Block.stoneSingleSlab.blockID);
            world.setBlock(i + 5, j + 10, k + 3, Block.stoneSingleSlab.blockID);
            world.setBlock(i + 5, j + 10, k + 2, Block.brick.blockID);
            world.setBlock(i + 5, j + 10, k + 1, Block.stairsWoodBirch.blockID);
            world.setBlock(i + 6, j + 10, k + 9, Block.stairsWoodBirch.blockID);
            world.setBlock(i + 6, j + 10, k + 8, Block.brick.blockID);
            world.setBlock(i + 6, j + 10, k + 7, Block.stoneSingleSlab.blockID);
            world.setBlock(i + 6, j + 10, k + 6, Block.stoneSingleSlab.blockID);
            world.setBlock(i + 6, j + 10, k + 5, Block.stoneSingleSlab.blockID);
            world.setBlock(i + 6, j + 10, k + 4, Block.stoneSingleSlab.blockID);
            world.setBlock(i + 6, j + 10, k + 3, Block.stoneSingleSlab.blockID);
            world.setBlock(i + 6, j + 10, k + 2, Block.brick.blockID);
            world.setBlock(i + 6, j + 10, k + 1, Block.stairsWoodBirch.blockID);
            world.setBlock(i + 7, j + 10, k + 9, Block.stairsWoodBirch.blockID);
            world.setBlock(i + 7, j + 10, k + 8, Block.brick.blockID);
            world.setBlock(i + 7, j + 10, k + 7, Block.stoneSingleSlab.blockID);
            world.setBlock(i + 7, j + 10, k + 6, Block.stoneSingleSlab.blockID);
            world.setBlock(i + 7, j + 10, k + 5, Block.stoneSingleSlab.blockID);
            world.setBlock(i + 7, j + 10, k + 4, Block.stoneSingleSlab.blockID);
            world.setBlock(i + 7, j + 10, k + 3, Block.stoneSingleSlab.blockID);
            world.setBlock(i + 7, j + 10, k + 2, Block.brick.blockID);
            world.setBlock(i + 7, j + 10, k + 1, Block.stairsWoodBirch.blockID);
            world.setBlock(i + 8, j + 10, k + 9, Block.stairsWoodBirch.blockID);
            world.setBlock(i + 8, j + 10, k + 8, Block.brick.blockID);
            world.setBlock(i + 8, j + 10, k + 7, Block.brick.blockID);
            world.setBlock(i + 8, j + 10, k + 6, Block.brick.blockID);
            world.setBlock(i + 8, j + 10, k + 5, Block.brick.blockID);
            world.setBlock(i + 8, j + 10, k + 4, Block.brick.blockID);
            world.setBlock(i + 8, j + 10, k + 3, Block.brick.blockID);
            world.setBlock(i + 8, j + 10, k + 2, Block.brick.blockID);
            world.setBlock(i + 8, j + 10, k + 1, Block.stairsWoodBirch.blockID);
            world.setBlock(i + 9, j + 10, k + 9, Block.stairsWoodBirch.blockID);
            world.setBlock(i + 9, j + 10, k + 8, Block.stairsWoodBirch.blockID);
            world.setBlock(i + 9, j + 10, k + 7, Block.stairsWoodBirch.blockID);
            world.setBlock(i + 9, j + 10, k + 6, Block.stairsWoodBirch.blockID);
            world.setBlock(i + 9, j + 10, k + 5, Block.stairsWoodBirch.blockID);
            world.setBlock(i + 9, j + 10, k + 4, Block.stairsWoodBirch.blockID);
            world.setBlock(i + 9, j + 10, k + 3, Block.stairsWoodBirch.blockID);
            world.setBlock(i + 9, j + 10, k + 2, Block.stairsWoodBirch.blockID);
            world.setBlock(i + 9, j + 10, k + 1, Block.stairsWoodBirch.blockID);
            world.setBlock(i + 1, j + 11, k + 9, Block.stairsStoneBrick.blockID);
            world.setBlock(i + 1, j + 11, k + 8, Block.stairsStoneBrick.blockID);
            world.setBlock(i + 1, j + 11, k + 7, Block.stairsStoneBrick.blockID);
            world.setBlock(i + 1, j + 11, k + 6, Block.stairsStoneBrick.blockID);
            world.setBlock(i + 1, j + 11, k + 5, Block.stairsStoneBrick.blockID);
            world.setBlock(i + 1, j + 11, k + 4, Block.stairsStoneBrick.blockID);
            world.setBlock(i + 1, j + 11, k + 3, Block.stairsStoneBrick.blockID);
            world.setBlock(i + 1, j + 11, k + 2, Block.stairsStoneBrick.blockID);
            world.setBlock(i + 1, j + 11, k + 1, Block.stairsStoneBrick.blockID);
            world.setBlock(i + 2, j + 11, k + 9, Block.stairsStoneBrick.blockID);
            world.setBlock(i + 2, j + 11, k + 8, Block.brick.blockID);
            world.setBlock(i + 2, j + 11, k + 7, Block.brick.blockID);
            world.setBlock(i + 2, j + 11, k + 6, Block.brick.blockID);
            world.setBlock(i + 2, j + 11, k + 5, Block.brick.blockID);
            world.setBlock(i + 2, j + 11, k + 4, Block.brick.blockID);
            world.setBlock(i + 2, j + 11, k + 3, Block.brick.blockID);
            world.setBlock(i + 2, j + 11, k + 2, Block.brick.blockID);
            world.setBlock(i + 2, j + 11, k + 1, Block.stairsStoneBrick.blockID);
            world.setBlock(i + 3, j + 11, k + 9, Block.stairsStoneBrick.blockID);
            world.setBlock(i + 3, j + 11, k + 8, Block.brick.blockID);
            world.setBlock(i + 3, j + 11, k + 2, Block.brick.blockID);
            world.setBlock(i + 3, j + 11, k + 1, Block.stairsStoneBrick.blockID);
            world.setBlock(i + 4, j + 11, k + 9, Block.stairsStoneBrick.blockID);
            world.setBlock(i + 4, j + 11, k + 8, Block.brick.blockID);
            world.setBlock(i + 4, j + 11, k + 2, Block.brick.blockID);
            world.setBlock(i + 4, j + 11, k + 1, Block.stairsStoneBrick.blockID);
            world.setBlock(i + 5, j + 11, k + 9, Block.stairsStoneBrick.blockID);
            world.setBlock(i + 5, j + 11, k + 8, Block.brick.blockID);
            world.setBlock(i + 5, j + 11, k + 5, Block.glowStone.blockID);
            world.setBlock(i + 5, j + 11, k + 2, Block.brick.blockID);
            world.setBlock(i + 5, j + 11, k + 1, Block.stairsStoneBrick.blockID);
            world.setBlock(i + 6, j + 11, k + 9, Block.stairsStoneBrick.blockID);
            world.setBlock(i + 6, j + 11, k + 8, Block.brick.blockID);
            world.setBlock(i + 6, j + 11, k + 2, Block.brick.blockID);
            world.setBlock(i + 6, j + 11, k + 1, Block.stairsStoneBrick.blockID);
            world.setBlock(i + 7, j + 11, k + 9, Block.stairsStoneBrick.blockID);
            world.setBlock(i + 7, j + 11, k + 8, Block.brick.blockID);
            world.setBlock(i + 7, j + 11, k + 2, Block.brick.blockID);
            world.setBlock(i + 7, j + 11, k + 1, Block.stairsStoneBrick.blockID);
            world.setBlock(i + 8, j + 11, k + 9, Block.stairsStoneBrick.blockID);
            world.setBlock(i + 8, j + 11, k + 8, Block.brick.blockID);
            world.setBlock(i + 8, j + 11, k + 7, Block.brick.blockID);
            world.setBlock(i + 8, j + 11, k + 6, Block.brick.blockID);
            world.setBlock(i + 8, j + 11, k + 5, Block.brick.blockID);
            world.setBlock(i + 8, j + 11, k + 4, Block.brick.blockID);
            world.setBlock(i + 8, j + 11, k + 3, Block.brick.blockID);
            world.setBlock(i + 8, j + 11, k + 2, Block.brick.blockID);
            world.setBlock(i + 8, j + 11, k + 1, Block.stairsStoneBrick.blockID);
            world.setBlock(i + 9, j + 11, k + 9, Block.stairsStoneBrick.blockID);
            world.setBlock(i + 9, j + 11, k + 8, Block.stairsStoneBrick.blockID);
            world.setBlock(i + 9, j + 11, k + 7, Block.stairsStoneBrick.blockID);
            world.setBlock(i + 9, j + 11, k + 6, Block.stairsStoneBrick.blockID);
            world.setBlock(i + 9, j + 11, k + 5, Block.stairsStoneBrick.blockID);
            world.setBlock(i + 9, j + 11, k + 4, Block.stairsStoneBrick.blockID);
            world.setBlock(i + 9, j + 11, k + 3, Block.stairsStoneBrick.blockID);
            world.setBlock(i + 9, j + 11, k + 2, Block.stairsStoneBrick.blockID);
            world.setBlock(i + 9, j + 11, k + 1, Block.stairsStoneBrick.blockID);
            world.setBlock(i + 2, j + 12, k + 8, Block.stairsStoneBrick.blockID);
            world.setBlock(i + 2, j + 12, k + 7, Block.stairsStoneBrick.blockID);
            world.setBlock(i + 2, j + 12, k + 6, Block.stairsStoneBrick.blockID);
            world.setBlock(i + 2, j + 12, k + 5, Block.stairsStoneBrick.blockID);
            world.setBlock(i + 2, j + 12, k + 4, Block.stairsStoneBrick.blockID);
            world.setBlock(i + 2, j + 12, k + 3, Block.stairsStoneBrick.blockID);
            world.setBlock(i + 2, j + 12, k + 2, Block.stairsStoneBrick.blockID);
            world.setBlock(i + 3, j + 12, k + 8, Block.stairsStoneBrick.blockID);
            world.setBlock(i + 3, j + 12, k + 7, Block.stoneSingleSlab.blockID);
            world.setBlock(i + 3, j + 12, k + 6, Block.stoneSingleSlab.blockID);
            world.setBlock(i + 3, j + 12, k + 5, Block.stoneSingleSlab.blockID);
            world.setBlock(i + 3, j + 12, k + 4, Block.stoneSingleSlab.blockID);
            world.setBlock(i + 3, j + 12, k + 3, Block.stoneSingleSlab.blockID);
            world.setBlock(i + 3, j + 12, k + 2, Block.stairsStoneBrick.blockID);
            world.setBlock(i + 4, j + 12, k + 8, Block.stairsStoneBrick.blockID);
            world.setBlock(i + 4, j + 12, k + 7, Block.stoneSingleSlab.blockID);
            world.setBlock(i + 4, j + 12, k + 6, Block.stoneSingleSlab.blockID);
            world.setBlock(i + 4, j + 12, k + 5, Block.stoneSingleSlab.blockID);
            world.setBlock(i + 4, j + 12, k + 4, Block.stoneSingleSlab.blockID);
            world.setBlock(i + 4, j + 12, k + 3, Block.stoneSingleSlab.blockID);
            world.setBlock(i + 4, j + 12, k + 2, Block.stairsStoneBrick.blockID);
            world.setBlock(i + 5, j + 12, k + 8, Block.stairsStoneBrick.blockID);
            world.setBlock(i + 5, j + 12, k + 7, Block.stoneSingleSlab.blockID);
            world.setBlock(i + 5, j + 12, k + 6, Block.stoneSingleSlab.blockID);
            world.setBlock(i + 5, j + 12, k + 5, Block.stoneSingleSlab.blockID);
            world.setBlock(i + 5, j + 12, k + 4, Block.stoneSingleSlab.blockID);
            world.setBlock(i + 5, j + 12, k + 3, Block.stoneSingleSlab.blockID);
            world.setBlock(i + 5, j + 12, k + 2, Block.stairsStoneBrick.blockID);
            world.setBlock(i + 6, j + 12, k + 8, Block.stairsStoneBrick.blockID);
            world.setBlock(i + 6, j + 12, k + 7, Block.stoneSingleSlab.blockID);
            world.setBlock(i + 6, j + 12, k + 6, Block.stoneSingleSlab.blockID);
            world.setBlock(i + 6, j + 12, k + 5, Block.stoneSingleSlab.blockID);
            world.setBlock(i + 6, j + 12, k + 4, Block.stoneSingleSlab.blockID);
            world.setBlock(i + 6, j + 12, k + 3, Block.stoneSingleSlab.blockID);
            world.setBlock(i + 6, j + 12, k + 2, Block.stairsStoneBrick.blockID);
            world.setBlock(i + 7, j + 12, k + 8, Block.stairsStoneBrick.blockID);
            world.setBlock(i + 7, j + 12, k + 7, Block.stoneSingleSlab.blockID);
            world.setBlock(i + 7, j + 12, k + 6, Block.stoneSingleSlab.blockID);
            world.setBlock(i + 7, j + 12, k + 5, Block.stoneSingleSlab.blockID);
            world.setBlock(i + 7, j + 12, k + 4, Block.stoneSingleSlab.blockID);
            world.setBlock(i + 7, j + 12, k + 3, Block.stoneSingleSlab.blockID);
            world.setBlock(i + 7, j + 12, k + 2, Block.stairsStoneBrick.blockID);
            world.setBlock(i + 8, j + 12, k + 8, Block.stairsStoneBrick.blockID);
            world.setBlock(i + 8, j + 12, k + 7, Block.stairsStoneBrick.blockID);
            world.setBlock(i + 8, j + 12, k + 6, Block.stairsStoneBrick.blockID);
            world.setBlock(i + 8, j + 12, k + 5, Block.stairsStoneBrick.blockID);
            world.setBlock(i + 8, j + 12, k + 4, Block.stairsStoneBrick.blockID);
            world.setBlock(i + 8, j + 12, k + 3, Block.stairsStoneBrick.blockID);
            world.setBlock(i + 8, j + 12, k + 2, Block.stairsStoneBrick.blockID);
        
        return true;
    }

}
